Workbook
Name IPP: #REF!
Name IPP: #REF!
Name IPP: #REF!
Name IPP: #REF!
Name IPP: #REF!
Name IPP: #REF!
Name IPP: #REF!
Name IPP: #REF!
Name IPP: #REF!
Name IPP: #REF!
Name IPP: #REF!
Name IPP: #REF!
Name IPP: #REF!
Name IPP: #REF!
Name IPP: #REF!
Name IPP: #REF!
Name IPP: #REF!
Name IPP: #REF!
Name IPP: #REF!
Name IPP: #REF!
Name IPP: #REF!
Name IPP: #REF!
Name IPP: #REF!
Name IPP: #REF!
Name IPP: #REF!
Name IPP: #REF!
Name IPP: #REF!
Name IPP: #REF!
Name IPP: #REF!
Name IPP: #REF!
Name IPP: #REF!
Name IPP: #REF!
Name IPP: #REF!
Name IPP: #REF!
Name ippp: #REF!
Name ippp: #REF!
Name ippp: #REF!
Name ippp: #REF!
Name ippp: #REF!
Name ippp: #REF!
Name ippp: #REF!
Name ippp: #REF!
Name ippp: #REF!
Name ippp: #REF!
Name ippp: #REF!
Name ippp: #REF!
Name ippp: #REF!
Name ippp: #REF!
Name ippp: #REF!
Name ippp: #REF!
Name ippp: #REF!
Name ippp: #REF!
Name ippp: #REF!
Name ippp: #REF!
Name ippp: #REF!
Name ippp: #REF!
Name ippp: #REF!
Name ippp: #REF!
Name ippp: #REF!
Name ippp: #REF!

Sheet 0
A1: LOAD DISPATCH CENTRE, NEPAL ELECTRICITY AUTHORITY DAILY SYSTEM OPERATION LOG FOR INPS | AG1: Installed Capacity (MW)
B2: Bhai | D2: Sim | F2: Ktm | H2: Brt | J2: Rainfall | K2: Bhai | L2: Sim | M2: Ktm | N2: Brt | AG2: =AG58 -> 1042.4 | AH2: IPP
V3: * other ipp reduced to 210 due to addition of rudi khola a in log sheet | X3: llkkjmj | AG3: =AG76 -> 489.91 | AH3: NEA RoR
A4: Nepali Date: | B4: ="2080/"&"10/"&INT(MID(CELL("filename",D6),FIND("]",CELL("filename",D6))+1,200)) -> 2080/10/0 | E4: ="2080/"&"10/"&INT(MID(CELL("filename",G6),FIND("]",CELL("filename",G6))+1,200)) -> 2080/10/0 | H4: =TEXT(E4,"dddd") -> 2080/10/0 | K4: ="Total Peak Supply(Inclusive of Export) ("&ROUND(B264,0)&" MW)"&" IPP = "&ROUND(B259,0)&" MW NEA RoR = "&ROUND(B260,0)&" MWImport = "&ROUND(B262,0)&" MW KL1+KL2+K3 = "&ROUND(B261,0) &" MW EXPORT = "&ROUND(B263,0) -> Total Peak Supply(Inclusive of Export) (0 MW) IPP = 0 MW NEA RoR = 0 MWImport = 0 MW KL1+KL2+K3 = 0 MW EXPORT = 0 | AG4: =AG80 -> 106 | AH4: NEA Storage
B5: =C92 -> 495.8 | C5: =D92 -> 507.2 | D5: =E92 -> 531.4 | E5: =F92 -> 520.5 | F5: =G92 -> 567.04 | G5: =H92 -> 571.7 | H5: =I92 -> 569.7 | I5: =J92 -> 620.5 | ... AE5: =AF92 -> 605.5 | AF5: =B92 -> 508.6
K6: ="Evening Peak "&ROUND(B264,0)&"MW at "&TRUNC(B265*24,0)&":"&ROUND((B265*24-TRUNC(B265*24,0))*60,0)&"hr at "&ROUND(B266,1)&"Hz "&A256&" "&ROUND(B256,0)&"MW at "&TRUNC(C256*24,0)&":"&ROUND((C256*24-TRUNC(C256*24,0))*6,0)&"0hr" -> Evening Peak 0MW at 0:0hr at 0Hz Morning Peak 1769MW at 7:30hr | AG6: =SUM(AG2:AG4) -> 1638.31 | AH6: Total Hydro
A7: ="Base Load="&ROUND(MIN($B$7:$AF$7),0) -> Base Load=1137 | B7: =B100 -> 1163.14 | C7: =C100 -> 1148.24 | D7: =D100 -> 1159.94 | E7: =E100 -> 1149.14 | F7: =F100 -> 1137.44 | G7: =G100 -> 1224.48 | H7: =H100 -> 1335.64 | I7: =I100 -> 1422.34 | ... AF7: =AF100 -> 1223.79
B8: Night Shift(Contd..) | M8: Morning Shift | S8: Day Shift | AB8: Night Shift
A9: Hrs. Source | B9: 0 | C9: 0.041666667 | D9: 0.083333333 | E9: 0.125 | F9: 0.16666667 | G9: 0.20833333 | H9: 0.22916667 | I9: 0.25 | J9: 0.27083333 | K9: 0.29166667 | L9: 0.3125 | M9: 0.33333333 | N9: 0.375 | O9: 0.41666667 | P9: 0.45833333 | Q9: 0.5 | R9: 0.54166667 | S9: 0.58333333 | T9: 0.625 | U9: 0.66666667 | V9: 0.70833333 | W9: 0.72916667 | X9: 0.75 | Y9: 0.77083333 | Z9: 0.79166667 | AA9: 0.8125 | AB9: 0.83333333 | AC9: 0.85416667 | AD9: 0.875 | AE9: 0.91666667 | AF9: 0.95833333 | AG9: Installed Capacity (MW)
A11: Solu Khola Dudhkoshi(86) | B11: 27.6 | C11: 27.6 | D11: 27.6 | E11: 27.6 | F11: 27.6 | G11: 27.6 | H11: 27.6 | I11: 27.6 | J11: 27.6 | K11: 27.6 | L11: 27.6 | M11: 28.9 | N11: 27.2 | O11: 27.2 | P11: 26.9 | Q11: 27.2 | R11: 28.9 | S11: 28.9 | T11: 28.9 | U11: 28.9 | V11: 28.9 | W11: 28.9 | X11: 28.9 | Y11: 28.9 | Z11: 28.9 | AA11: 28.9 | AB11: 30.5 | AC11: 30.5 | AD11: 30.5 | AE11: 30.5 | AF11: 30.5 | AG11: 86 | AH11: =MAX(B11:AF11) -> 30.5 | AI11: =MIN(B11:AF11) -> 26.9
A12: Likhu-II(55) | B12: 9.8 | C12: 9.8 | D12: 9.8 | E12: 9.8 | F12: 9.8 | G12: 9.8 | H12: 9.8 | I12: 9.8 | J12: 9.8 | K12: 9.8 | L12: 9.8 | M12: 9.8 | N12: 9.8 | O12: 9.8 | P12: 9.8 | Q12: 9.8 | R12: 9.8 | S12: 9.8 | T12: 9.8 | U12: 9.8 | V12: 9.8 | W12: 9.8 | X12: 9.8 | Y12: 9.8 | Z12: 9.8 | AA12: 9.8 | AB12: 9.8 | AC12: 9.8 | AD12: 9.8 | AE12: 9.8 | AF12: 9.8 | AG12: 54 | AH12: =MAX(B12:AF12) -> 9.8 | AI12: =MIN(B12:AF12) -> 9.8
A13: Super Dordi (54) | B13: 12 | C13: 12 | D13: 12 | E13: 12 | F13: 12 | G13: 12 | H13: 12 | I13: 12 | J13: 12 | K13: 12 | L13: 12 | M13: 12 | N13: 12 | O13: 12 | P13: 12 | Q13: 12 | R13: 10.3 | S13: 10.3 | T13: 10.3 | U13: 10.3 | V13: 10.3 | W13: 10.3 | X13: 10.3 | Y13: 10.3 | Z13: 10.3 | AA13: 10.3 | AB13: 10.3 | AC13: 10.3 | AD13: 10.3 | AE13: 10.3 | AF13: 10.3 | AG13: 54 | AH13: =MAX(B13:AF13) -> 12 | AI13: =MIN(B13:AF13) -> 10.3
A14: Likhu-IV(52.4) | B14: 13.9 | C14: 13.9 | D14: 13.9 | E14: 13.9 | F14: 13.9 | G14: 13.9 | H14: 13.9 | I14: 13.9 | J14: 13.9 | K14: 13.9 | L14: 13.9 | M14: 12.5 | N14: 12.5 | O14: 12.5 | P14: 12.5 | Q14: 12.5 | R14: 9 | S14: 9 | T14: 9 | U14: 9 | V14: 9 | W14: 9 | X14: 9 | Y14: 9 | Z14: 9 | AA14: 9 | AB14: 16.4 | AC14: 16.4 | AD14: 16.4 | AE14: 16.4 | AF14: 16.4 | AG14: 52.4 | AH14: =MAX(B14:AF14) -> 16.4 | AI14: =MIN(B14:AF14) -> 9
A15: Upper Marsyangdi "A"(50) | B15: 29.8 | C15: 29.8 | D15: 29.8 | E15: 29.8 | F15: 29.8 | G15: 29.8 | H15: 29.8 | I15: 29.8 | J15: 29.8 | K15: 29.8 | L15: 29.8 | M15: 29.6 | N15: 29.6 | O15: 29.6 | P15: 29.6 | Q15: 29.6 | R15: 28.5 | S15: 28.5 | T15: 28.5 | U15: 28.5 | V15: 28.5 | W15: 28.5 | X15: 28.5 | Y15: 28.5 | Z15: 28.5 | AA15: 28.5 | AB15: 28.3 | AC15: 28.3 | AD15: 28.3 | AE15: 28.3 | AF15: 28.3 | AG15: 50 | AH15: =MAX(B15:AF15) -> 29.8 | AI15: =MIN(B15:AF15) -> 28.3
A16: Upper Bhotekoshi Khola(45) | B16: 16.6 | C16: 16.6 | D16: 16.6 | E16: 16.6 | F16: 16.6 | G16: 16.6 | H16: 16.6 | I16: 16.6 | J16: 16.6 | K16: 16.6 | L16: 16.6 | M16: 15.2 | N16: 15.2 | O16: 15.2 | P16: 15.2 | Q16: 15.2 | R16: 14.7 | S16: 14.7 | T16: 14.7 | U16: 14.7 | V16: 14.7 | W16: 14.7 | X16: 14.7 | Y16: 14.7 | Z16: 14.7 | AA16: 14.7 | AB16: 17.2 | AC16: 17.2 | AD16: 17.2 | AE16: 17.2 | AF16: 17.2 | AG16: 45 | AH16: =MAX(B16:AF16) -> 17.2 | AI16: =MIN(B16:AF16) -> 14.7
A17: Super Madi ( 44 ) | B17: 14 | C17: 14 | D17: 14 | E17: 14 | F17: 14 | G17: 14 | H17: 14 | I17: 14 | J17: 14 | K17: 14 | L17: 14 | M17: 14 | N17: 14 | O17: 14 | P17: 14 | Q17: 14 | R17: 14 | S17: 14 | T17: 14 | U17: 14 | V17: 14 | W17: 14 | X17: 14 | Y17: 14 | Z17: 14 | AA17: 14 | AB17: 14 | AC17: 14 | AD17: 14 | AE17: 14 | AF17: 14 | AG17: 44 | AH17: =MAX(B17:AG17) -> 44 | AI17: =MIN(B17:AG17) -> 14
A18: Mistri Khola(42) | B18: 8.5 | C18: 8.5 | D18: 8.5 | E18: 8.5 | F18: 8.5 | G18: 8.5 | H18: 8.5 | I18: 8.5 | J18: 8.5 | K18: 8.5 | L18: 8.5 | M18: 8.5 | N18: 8.5 | O18: 8.5 | P18: 8.5 | Q18: 8.5 | R18: 8.5 | S18: 8.5 | T18: 8.5 | U18: 8.5 | V18: 8.5 | W18: 8.5 | X18: 8.5 | Y18: 8.5 | Z18: 8.5 | AA18: 8.5 | AB18: 7.5 | AC18: 7.5 | AD18: 7.5 | AE18: 7.5 | AF18: 7.5 | AG18: 42 | AH18: =MAX(B18:AF18) -> 8.5 | AI18: =MIN(B18:AF18) -> 7.5
A19: Upper Chameliya(40) | B19: 15 | C19: 15 | D19: 15 | E19: 15 | F19: 15 | G19: 15 | H19: 15 | I19: 15 | J19: 15 | K19: 15 | L19: 15 | M19: 15 | N19: 15 | O19: 15 | P19: 15 | Q19: 15 | R19: 15 | S19: 15 | T19: 15 | U19: 15 | V19: 15 | W19: 15 | X19: 15 | Y19: 15 | Z19: 15 | AA19: 15 | AB19: 12.2 | AC19: 12.2 | AD19: 12.2 | AE19: 12.2 | AF19: 12.2 | AG19: 38.46 | AH19: =MAX(B19:AF19) -> 15 | AI19: =MIN(B19:AF19) -> 12.2
A20: Upper Kalanga Gad(38.46) | B20: 10 | C20: 10 | D20: 10 | E20: 10 | F20: 10 | G20: 10 | H20: 10 | I20: 10 | J20: 10 | K20: 10 | L20: 10 | M20: 10 | N20: 10 | O20: 10 | P20: 10 | Q20: 10 | R20: 10 | S20: 10 | T20: 10 | U20: 10 | V20: 10 | W20: 10 | X20: 10 | Y20: 10 | Z20: 10 | AA20: 10 | AB20: 7.8 | AC20: 7.8 | AD20: 7.8 | AE20: 7.8 | AF20: 7.8 | AG20: 38.46 | AH20: =MAX(B20:AF20) -> 10 | AI20: =MIN(B20:AF20) -> 7.8
A21: Upper Balefi (36) | B21: 13 | C21: 13 | D21: 13 | E21: 13 | F21: 13 | G21: 13 | H21: 13 | I21: 13 | J21: 13 | K21: 13 | L21: 13 | M21: 13 | N21: 13 | O21: 13 | P21: 13 | Q21: 13 | R21: 13 | S21: 13 | T21: 13 | U21: 13 | V21: 13 | W21: 13 | X21: 13 | Y21: 13 | Z21: 13 | AA21: 13 | AB21: 13 | AC21: 13 | AD21: 13 | AE21: 13 | AF21: 13 | AG21: 36 | AH21: =MAX(B21:AF21) -> 13 | AI21: =MIN(B21:AF21) -> 13
A22: Nyadi(30) | B22: 8.4 | C22: 8.4 | D22: 8.4 | E22: 8.4 | F22: 8.4 | G22: 8.4 | H22: 8.4 | I22: 8.4 | J22: 8.4 | K22: 8.4 | L22: 8.4 | M22: 7.8 | N22: 7.8 | O22: 7.8 | P22: 7.8 | Q22: 7.8 | R22: 7.8 | S22: 7.8 | T22: 7.8 | U22: 7.8 | V22: 7.8 | W22: 7.8 | X22: 7.8 | Y22: 7.8 | Z22: 7.8 | AA22: 7.8 | AB22: 8.8 | AC22: 8.8 | AD22: 8.8 | AE22: 8.8 | AF22: 8.8 | AG22: 30 | AH22: =MAX(B22:AF22) -> 8.8 | AI22: =MIN(B22:AF22) -> 7.8
A23: Likhu Khola A(29.04) | B23: 9 | C23: 9 | D23: 9 | E23: 9 | F23: 9 | G23: 9 | H23: 9 | I23: 9 | J23: 9 | K23: 9 | L23: 9 | M23: 9 | N23: 9 | O23: 9 | P23: 9 | Q23: 9 | R23: 9 | S23: 9 | T23: 9 | U23: 9 | V23: 9 | W23: 9 | X23: 9 | Y23: 9 | Z23: 9 | AA23: 9 | AB23: 9 | AC23: 9 | AD23: 9 | AE23: 9 | AF23: 9 | AG23: 24.2 | AH23: =MAX(B23:AF23) -> 9 | AI23: =MIN(B23:AF23) -> 9
A24: Lower Likhu(28) | B24: 8.6 | C24: 8.6 | D24: 8.6 | E24: 8.6 | F24: 8.6 | G24: 8.6 | H24: 8.6 | I24: 8.6 | J24: 8.6 | K24: 8.6 | L24: 8.6 | M24: 8.2 | N24: 8.2 | O24: 8.2 | P24: 8.2 | Q24: 8.2 | R24: 7.2 | S24: 7.2 | T24: 7.2 | U24: 7.2 | V24: 7.2 | W24: 7.2 | X24: 7.2 | Y24: 7.2 | Z24: 7.2 | AA24: 7.2 | AB24: 7.2 | AC24: 7.2 | AD24: 7.2 | AE24: 7.2 | AF24: 7.2 | AG24: 28 | AH24: =MAX(B24:AF24) -> 8.6 | AI24: =MIN(B24:AF24) -> 7.2
A25: Dordi(27) | B25: 7 | C25: 7 | D25: 7 | E25: 7 | F25: 7 | G25: 7 | H25: 7 | I25: 7 | J25: 7 | K25: 7 | L25: 7 | M25: 7.4 | N25: 7.4 | O25: 7.4 | P25: 7.4 | Q25: 7.4 | R25: 6.7 | S25: 6.7 | T25: 6.7 | U25: 6.7 | V25: 6.7 | W25: 6.7 | X25: 6.7 | Y25: 6.7 | Z25: 6.7 | AA25: 6.7 | AB25: 6.7 | AC25: 6.7 | AD25: 6.7 | AE25: 6.7 | AF25: 6.7 | AG25: 30 | AH25: =MAX(B25:AF25) -> 7.4 | AI25: =MIN(B25:AF25) -> 6.7
A26: Upper Madi(25) | B26: 8.9 | C26: 8.9 | D26: 8.9 | E26: 8.9 | F26: 8.9 | G26: 8.9 | H26: 8.9 | I26: 8.9 | J26: 8.9 | K26: 8.9 | L26: 8.9 | M26: 8.3 | N26: 8.3 | O26: 8.3 | P26: 8.3 | Q26: 8.3 | R26: 8.2 | S26: 8.2 | T26: 8.2 | U26: 8.2 | V26: 8.2 | W26: 8.2 | X26: 8.2 | Y26: 8.2 | Z26: 8.2 | AA26: 8.2 | AB26: 8.2 | AC26: 8.2 | AD26: 8.2 | AE26: 8.2 | AF26: 8.2 | AG26: 25 | AH26: =MAX(B26:AF26) -> 8.9 | AI26: =MIN(B26:AF26) -> 8.2
A27: Kabeli B-1(25) | B27: 5 | C27: 5 | D27: 5 | E27: 5 | F27: 5 | G27: 5 | H27: 5 | I27: 5 | J27: 5 | K27: 5 | L27: 5 | M27: 5 | N27: 5 | O27: 5 | P27: 5 | Q27: 5 | R27: 5 | S27: 5 | T27: 5 | U27: 5 | V27: 5 | W27: 5 | X27: 5 | Y27: 5 | Z27: 5 | AA27: 5 | AB27: 5 | AC27: 5 | AD27: 5 | AE27: 5 | AF27: 5 | AG27: 25 | AH27: =MAX(B27:AF27) -> 5 | AI27: =MIN(B27:AF27) -> 5
A28: Singati Khola(25) | B28: 6 | C28: 6 | D28: 6 | E28: 6 | F28: 6 | G28: 6 | H28: 6 | I28: 6 | J28: 6 | K28: 6 | L28: 6 | M28: 6 | N28: 6 | O28: 6 | P28: 6 | Q28: 6 | R28: 6 | S28: 6 | T28: 6 | U28: 6 | V28: 6 | W28: 6 | X28: 6 | Y28: 6 | Z28: 6 | AA28: 6 | AB28: 6 | AC28: 6 | AD28: 6 | AE28: 6 | AF28: 6 | AG28: 25 | AH28: =MAX(B28:AF28) -> 6 | AI28: =MIN(B28:AF28) -> 6
A29: Upper Dordi (25) | B29: 8.1 | C29: 8.1 | D29: 8.1 | E29: 8.1 | F29: 8.1 | G29: 8.1 | H29: 8.1 | I29: 8.1 | J29: 8.1 | K29: 8.1 | L29: 8.1 | M29: 7.6 | N29: 7.6 | O29: 7.6 | P29: 7.6 | Q29: 7.6 | R29: 7.4 | S29: 7.4 | T29: 7.4 | U29: 7.4 | V29: 7.4 | W29: 7.4 | X29: 7.4 | Y29: 7.4 | Z29: 7.4 | AA29: 7.4 | AB29: 7.4 | AC29: 7.4 | AD29: 7.4 | AE29: 7.4 | AF29: 7.4 | AG29: 25 | AH29: =MAX(B29:AF29) -> 8.1 | AI29: =MIN(B29:AF29) -> 7.4
... A56: Other IPP Total | B56: 150 | C56: 150 | D56: 150 | E56: 150 | F56: 150 | G56: 150 | H56: 150 | I56: 150 | J56: 150 | K56: 150 | L56: 150 | M56: 150 | N56: 150 | O56: 150 | P56: 150 | Q56: 150 | R56: 150 | S56: 150 | T56: 150 | U56: 150 | V56: 150 | W56: 150 | X56: 150 | Y56: 150 | Z56: 150 | AA56: 150 | AB56: 150 | AC56: 150 | AD56: 150 | AE56: 150 | AF56: 150 | AG56: 85 | AH56: =MAX(B56:AF56) -> 150 | AI56: =MIN(B56:AF56) -> 150
A57: Kabeli Corridor | B57: 25 | C57: 25 | D57: 25 | E57: 25 | F57: 25 | G57: 25 | H57: 25 | I57: 25 | J57: 25 | K57: 25 | L57: 25 | M57: =2.8+11.7 -> 14.5 | N57: =13.8+3.8 -> 17.6 | O57: =14+4.1 -> 18.1 | P57: =13.8+4 -> 17.8 | Q57: =14.4+4.6 -> 19 | R57: =3.9+12.7 -> 16.6 | S57: 21.6 | T57: 21.6 | U57: 21.6 | V57: 21.6 | W57: 21.6 | X57: 21.6 | Y57: 21.6 | Z57: 21.6 | AA57: 21.6 | AB57: 18.1 | AC57: 18.1 | AD57: 18.1 | AE57: 18.1 | AF57: 18.1 | AG57: 240 | AH57: =MAX(B57:AF57) -> 25 | AI57: =MIN(B57:AF57) -> 14.5
A58: Total IPP | B58: =SUM(B11:B56) -> 496.9 | C58: =SUM(C11:C56) -> 496.9 | D58: =SUM(D11:D56) -> 496.9 | E58: =SUM(E11:E56) -> 496.9 | F58: =SUM(F11:F56) -> 496.9 | G58: =SUM(G11:G56) -> 496.9 | H58: =SUM(H11:H56) -> 496.9 | I58: =SUM(I11:I56) -> 496.9 | ... AF58: =SUM(AF11:AF56) -> 484.25 | AG58: =SUM(AG14:AG56) -> 1042.4 | AH58: =MAX(B58:AF58) -> 496.9 | AI58: =MIN(B58:AF58) -> 478.6
A59: Upper Tamakoshi(456) | B59: 0 | C59: 0 | D59: 0 | E59: 0 | F59: 0 | G59: 0 | H59: 60 | I59: 75 | J59: 120 | K59: 260 | L59: 420 | M59: 405 | N59: 225 | O59: 125 | P59: 15 | Q59: 15 | R59: 0 | S59: 0 | T59: 0 | U59: 0 | V59: 0 | W59: 30 | X59: 210 | Y59: 345 | Z59: 340 | AA59: 350 | AB59: 235 | AC59: 200 | AD59: 100 | AE59: 0 | AF59: 0 | AG59: 456 | AH59: =MAX(B59:AF59) -> 420 | AI59: =MIN(B59:AF59) -> 0
A60: Khimti Khola(60) | B60: 30 | C60: 30 | D60: 30 | E60: 30 | F60: 30 | G60: 30 | H60: 30 | I60: 30 | J60: 30 | K60: 30 | L60: 30 | M60: 30 | N60: 30 | O60: 30 | P60: 30 | Q60: 30 | R60: 30 | S60: 30 | T60: 30 | U60: 30 | V60: 30 | W60: 30 | X60: 30 | Y60: 30 | Z60: 30 | AA60: 30 | AB60: 30 | AC60: 30 | AD60: 30 | AE60: 30 | AF60: 30 | AG60: 60 | AH60: =MAX(B60:AF60) -> 30 | AI60: =MIN(B60:AF60) -> 30
A61: Chilime(22.1) | B61: 10.2 | C61: 10.2 | D61: 10.2 | E61: 10.2 | F61: 10.2 | G61: 10.2 | H61: 10.2 | I61: 10.2 | J61: 10.2 | K61: 10.2 | L61: 10.2 | M61: 10.2 | N61: 10.2 | O61: 10.2 | P61: 10.2 | Q61: 10.2 | R61: 10.2 | S61: 10.2 | T61: 10.2 | U61: 10.2 | V61: 10.2 | W61: 10.2 | X61: 10.2 | Y61: 16 | Z61: 10.2 | AA61: 10.2 | AB61: 10.2 | AC61: 10.2 | AD61: 10 | AE61: 10 | AF61: 10 | AG61: 22.1 | AH61: =MAX(B61:AF61) -> 16 | AI61: =MIN(B61:AF61) -> 10
A62: Total NEA SUBSIDIARIES | B62: =SUM(B59:B61) -> 40.2 | C62: =SUM(C59:C61) -> 40.2 | D62: =SUM(D59:D61) -> 40.2 | E62: =SUM(E59:E61) -> 40.2 | F62: =SUM(F59:F61) -> 40.2 | G62: =SUM(G59:G61) -> 40.2 | H62: =SUM(H59:H61) -> 100.2 | I62: =SUM(I59:I61) -> 115.2 | ... AG62: =SUM(AG59:AG61) -> 538.1 | AH62: =MAX(B62:AF62) -> 460.2 | AI62: =MIN(B62:AF62) -> 40
A63: KGA(144) | B63: 0 | C63: 0 | D63: 0 | E63: 0 | F63: 0 | G63: 30.5 | H63: 47 | I63: 96.7 | J63: 97.7 | K63: 83.2 | L63: 81.5 | M63: 97.7 | N63: 81.7 | O63: 65.2 | P63: 61.5 | Q63: 61.5 | R63: 61.2 | S63: 61.2 | T63: 60.2 | U63: 132.6 | V63: 91.7 | W63: 61.2 | X63: 105.8 | Y63: 143.9 | Z63: 143.9 | AA63: 143 | AB63: 136.2 | AC63: 98 | AD63: 97 | AE63: 77 | AF63: 0 | AG63: 144 | AH63: =MAX(B63:AF63) -> 143.9 | AI63: =MIN(B63:AF63) -> 0
A64: Middle MRS(70) | B64: 0 | C64: 0 | D64: 0 | E64: 0 | F64: 0 | G64: 0 | H64: 25 | I64: 35 | J64: 35 | K64: 35 | L64: 50 | M64: 60 | N64: 60 | O64: 60 | P64: 43 | Q64: 43 | R64: 43 | S64: 45 | T64: 0 | U64: 25 | V64: 25 | W64: 25 | X64: 45 | Y64: 69 | Z64: 69 | AA64: 50 | AB64: 50 | AC64: 35 | AD64: 35 | AE64: 35 | AF64: 0 | AG64: 70 | AH64: =MAX(B64:AF64) -> 69 | AI64: =MIN(B64:AF64) -> 0
A65: MRS(69) | B65: 34.5 | C65: 34.7 | D65: 34.8 | E65: 0 | F65: 0 | G65: 0 | H65: 0 | I65: 0 | J65: 43.3 | K65: 45.4 | L65: 45.9 | M65: 61.9 | N65: 61.5 | O65: 61.1 | P65: 37.3 | Q65: 36.9 | R65: 36.6 | S65: 36.6 | T65: 36.7 | U65: 54.8 | V65: 40.4 | W65: 35.3 | X65: 52.1 | Y65: 67.3 | Z65: 67.3 | AA65: 67.7 | AB65: 67.3 | AC65: 44 | AD65: 34 | AE65: 34 | AF65: 17 | AG65: 69 | AH65: =MAX(B65:AF65) -> 67.7 | AI65: =MIN(B65:AF65) -> 0
A66: U Trisuli 3A(60) | B66: 42.1 | C66: 39.8 | D66: 40 | E66: 39.8 | F66: 39 | G66: 39 | H66: 39 | I66: 39 | J66: 39 | K66: 37.3 | L66: 37.3 | M66: 37.6 | N66: 39.3 | O66: 40.3 | P66: 40 | Q66: 40 | R66: 36.3 | S66: 36.3 | T66: 36.3 | U66: 36.3 | V66: 36.3 | W66: 36.3 | X66: 36.3 | Y66: 36.3 | Z66: 36.3 | AA66: 38 | AB66: 38 | AC66: 38 | AD66: 38 | AE66: 38 | AF66: 38 | AG66: 60 | AH66: =MAX(B66:AF66) -> 42.1 | AI66: =MIN(B66:AF66) -> 36.3
A67: CHM(30) | B67: 0 | C67: 0 | D67: 0 | E67: 0 | F67: 0 | G67: 10 | H67: 15 | I67: 29 | J67: 23 | K67: 23 | L67: 29 | M67: 29 | N67: 27 | O67: 0 | P67: 0 | Q67: 0 | R67: 0 | S67: 0 | T67: 0 | U67: 0 | V67: 0 | W67: 0 | X67: 23 | Y67: 29 | Z67: 29 | AA67: 28 | AB67: 10 | AC67: 10 | AD67: 10 | AE67: 0 | AF67: 0 | AG67: 30 | AH67: =MAX(B67:AF67) -> 29 | AI67: =MIN(B67:AF67) -> 0
...

Sheet 1
A1: LOAD DISPATCH CENTRE, NEPAL ELECTRICITY AUTHORITY DAILY SYSTEM OPERATION LOG FOR INPS | AG1: Installed Capacity (MW)
B2: Bhai | D2: Sim | F2: Ktm | H2: Brt | J2: Rainfall | K2: Bhai | L2: Sim | M2: Ktm | N2: Brt | AG2: =AG58 -> 1042.4 | AH2: IPP
V3: * other ipp reduced to 210 due to addition of rudi khola a in log sheet | X3: llkkjmj | AG3: =AG76 -> 489.91 | AH3: NEA RoR
A4: Nepali Date: | B4: ="2080/"&"10/"&INT(MID(CELL("filename",D6),FIND("]",CELL("filename",D6))+1,200)) -> 2080/10/1 | E4: ="2080/"&"10/"&INT(MID(CELL("filename",G6),FIND("]",CELL("filename",G6))+1,200)) -> 2080/10/1 | H4: =TEXT(E4,"dddd") -> Tuesday | K4: ="Total Peak Supply(Inclusive of Export) ("&ROUND(B264,0)&" MW)"&" IPP = "&ROUND(B259,0)&" MW NEA RoR = "&ROUND(B260,0)&" MWImport = "&ROUND(B262,0)&" MW KL1+KL2+K3 = "&ROUND(B261,0) &" MW EXPORT = "&ROUND(B263,0) -> Total Peak Supply(Inclusive of Export) (0 MW) IPP = 0 MW NEA RoR = 0 MWImport = 0 MW KL1+KL2+K3 = 0 MW EXPORT = 0 | AG4: =AG80 -> 106 | AH4: NEA Storage
B5: =C92 -> 598 | C5: =D92 -> 559.6 | D5: =E92 -> 566.1 | E5: =F92 -> 571.9 | F5: =G92 -> 541.1 | G5: =H92 -> 564.8 | H5: =I92 -> 532.9 | I5: =J92 -> 618.1 | ... AE5: =AF92 -> 574.9 | AF5: =B92 -> 556
K6: ="Evening Peak "&ROUND(B264,0)&"MW at "&TRUNC(B265*24,0)&":"&ROUND((B265*24-TRUNC(B265*24,0))*60,0)&"hr at "&ROUND(B266,1)&"Hz "&A256&" "&ROUND(B256,0)&"MW at "&TRUNC(C256*24,0)&":"&ROUND((C256*24-TRUNC(C256*24,0))*6,0)&"0hr" -> Evening Peak 0MW at 0:0hr at 0Hz Morning Peak 1791MW at 8:00hr | AG6: =SUM(AG2:AG4) -> 1638.31 | AH6: Total Hydro
A7: ="Base Load="&ROUND(MIN($B$7:$AF$7),0) -> Base Load=1157 | B7: =B100 -> 1157.29 | C7: =C100 -> 1199.29 | D7: =D100 -> 1160.89 | E7: =E100 -> 1167.69 | F7: =F100 -> 1185.19 | G7: =G100 -> 1224.89 | H7: =H100 -> 1342.59 | I7: =I100 -> 1325.69 | ... AF7: =AF100 -> 1233.09
B8: Night Shift(Contd..) | M8: Morning Shift | S8: Day Shift | AB8: Night Shift
A9: Hrs. Source | B9: 0 | C9: 0.041666667 | D9: 0.083333333 | E9: 0.125 | F9: 0.16666667 | G9: 0.20833333 | H9: 0.22916667 | I9: 0.25 | J9: 0.27083333 | K9: 0.29166667 | L9: 0.3125 | M9: 0.33333333 | N9: 0.375 | O9: 0.41666667 | P9: 0.45833333 | Q9: 0.5 | R9: 0.54166667 | S9: 0.58333333 | T9: 0.625 | U9: 0.66666667 | V9: 0.70833333 | W9: 0.72916667 | X9: 0.75 | Y9: 0.77083333 | Z9: 0.79166667 | AA9: 0.8125 | AB9: 0.83333333 | AC9: 0.85416667 | AD9: 0.875 | AE9: 0.91666667 | AF9: 0.95833333 | AG9: Installed Capacity (MW)
A11: Solu Khola Dudhkoshi(86) | B11: 30.5 | C11: 30.5 | D11: 30.5 | E11: 29.5 | F11: 29 | G11: 28.9 | H11: 28.9 | I11: 28.9 | J11: 28.9 | K11: 28.9 | L11: 28.9 | M11: 28.9 | N11: 27.6 | O11: 25.3 | P11: 26.2 | Q11: 26.3 | R11: 28.3 | S11: 28.3 | T11: 28.3 | U11: 28.3 | V11: 28.3 | W11: 28.3 | X11: 28.3 | Y11: 28.3 | Z11: 15 | AA11: 28.3 | AB11: 28.3 | AC11: 28.3 | AD11: 28.3 | AE11: 28.3 | AF11: 28.3 | AG11: 86 | AH11: =MAX(B11:AF11) -> 30.5 | AI11: =MIN(B11:AF11) -> 15
A12: Likhu-II(55) | B12: 9.8 | C12: 9.8 | D12: 9.8 | E12: 9.8 | F12: 9.8 | G12: 9.8 | H12: 9.8 | I12: 9.8 | J12: 9.8 | K12: 9.8 | L12: 9.8 | M12: 9.8 | N12: 9.8 | O12: 9.8 | P12: 9.8 | Q12: 9.8 | R12: 9.8 | S12: 9.8 | T12: 9.8 | U12: 9.8 | V12: 9.8 | W12: 9.8 | X12: 9.8 | Y12: 9.8 | Z12: 9.8 | AA12: 9.8 | AB12: 9.8 | AC12: 9.8 | AD12: 9.8 | AE12: 9.8 | AF12: 9.8 | AG12: 54 | AH12: =MAX(B12:AF12) -> 9.8 | AI12: =MIN(B12:AF12) -> 9.8
A13: Super Dordi (54) | B13: 10.3 | C13: 10.3 | D13: 10.3 | E13: 10.3 | F13: 10.3 | G13: 10.3 | H13: 10.3 | I13: 10.3 | J13: 10.3 | K13: 10.3 | L13: 10.3 | M13: 10.3 | N13: 10.3 | O13: 10.3 | P13: 10.3 | Q13: 10.3 | R13: 10.3 | S13: 10.3 | T13: 10.3 | U13: 10.3 | V13: 10.3 | W13: 10.3 | X13: 10.3 | Y13: 10.3 | Z13: 10.3 | AA13: 10.3 | AB13: 10.3 | AC13: 10.3 | AD13: 10.3 | AE13: 10.3 | AF13: 10.3 | AG13: 54 | AH13: =MAX(B13:AF13) -> 10.3 | AI13: =MIN(B13:AF13) -> 10.3
A14: Likhu-IV(52.4) | B14: 16.4 | C14: 16.4 | D14: 16.4 | E14: 16.4 | F14: 16.4 | G14: 15.3 | H14: 15.3 | I14: 15.3 | J14: 15.3 | K14: 15.3 | L14: 15.3 | M14: 15.3 | N14: 15.3 | O14: 15.3 | P14: 15.3 | Q14: 15.3 | R14: 15.3 | S14: 15.3 | T14: 15.3 | U14: 15.3 | V14: 15.3 | W14: 15.3 | X14: 15.3 | Y14: 15.3 | Z14: 15.3 | AA14: 15.3 | AB14: 15.3 | AC14: 15.3 | AD14: 15.3 | AE14: 15.3 | AF14: 15.3 | AG14: 52.4 | AH14: =MAX(B14:AF14) -> 16.4 | AI14: =MIN(B14:AF14) -> 15.3
A15: Upper Marsyangdi "A"(50) | B15: 28.3 | C15: 28.3 | D15: 28.3 | E15: 28.3 | F15: 28.3 | G15: 29.1 | H15: 29.1 | I15: 29.1 | J15: 29.1 | K15: 29.1 | L15: 29.1 | M15: 29.1 | N15: 29.1 | O15: 29.1 | P15: 29.1 | Q15: 29.1 | R15: 29.1 | S15: 29.1 | T15: 29.1 | U15: 29.1 | V15: 29.1 | W15: 29.1 | X15: 29.1 | Y15: 29.1 | Z15: 29.1 | AA15: 29.1 | AB15: 29.1 | AC15: 29.1 | AD15: 29.1 | AE15: 29.1 | AF15: 29.1 | AG15: 50 | AH15: =MAX(B15:AF15) -> 29.1 | AI15: =MIN(B15:AF15) -> 28.3
A16: Upper Bhotekoshi Khola(45) | B16: 17.2 | C16: 17.2 | D16: 17.2 | E16: 17.2 | F16: 17.2 | G16: 16.6 | H16: 16.6 | I16: 16.6 | J16: 16.6 | K16: 16.6 | L16: 16.6 | M16: 16.6 | N16: 16.6 | O16: 16.6 | P16: 16.6 | Q16: 16.6 | R16: 16.6 | S16: 16.6 | T16: 16.6 | U16: 16.6 | V16: 16.6 | W16: 16.6 | X16: 16.6 | Y16: 16.6 | Z16: 16.6 | AA16: 16.6 | AB16: 16.6 | AC16: 16.6 | AD16: 16.6 | AE16: 16.6 | AF16: 16.6 | AG16: 45 | AH16: =MAX(B16:AF16) -> 17.2 | AI16: =MIN(B16:AF16) -> 16.6
A17: Super Madi ( 44 ) | B17: 14 | C17: 14 | D17: 14 | E17: 14 | F17: 14 | G17: 14 | H17: 14 | I17: 14 | J17: 14 | K17: 14 | L17: 14 | M17: 14 | N17: 14 | O17: 14 | P17: 14 | Q17: 14 | R17: 14 | S17: 14 | T17: 14 | U17: 14 | V17: 14 | W17: 14 | X17: 14 | Y17: 14 | Z17: 14 | AA17: 14 | AB17: 14 | AC17: 14 | AD17: 14 | AE17: 14 | AF17: 14 | AG17: 44 | AH17: =MAX(B17:AG17) -> 44 | AI17: =MIN(B17:AG17) -> 14
A18: Mistri Khola(42) | B18: 7.5 | C18: 7.5 | D18: 7.5 | E18: 7.5 | F18: 7.5 | G18: 8 | H18: 8 | I18: 8 | J18: 8 | K18: 8 | L18: 8 | M18: 8 | N18: 8 | O18: 8 | P18: 8 | Q18: 8 | R18: 8 | S18: 8 | T18: 8 | U18: 8 | V18: 8 | W18: 8 | X18: 8 | Y18: 8 | Z18: 8 | AA18: 8 | AB18: 8 | AC18: 8 | AD18: 8 | AE18: 8 | AF18: 8 | AG18: 42 | AH18: =MAX(B18:AF18) -> 8 | AI18: =MIN(B18:AF18) -> 7.5
A19: Upper Chameliya(40) | B19: 12.2 | C19: 12.2 | D19: 12.2 | E19: 12.2 | F19: 12.2 | G19: 12.2 | H19: 12.2 | I19: 12.2 | J19: 12.2 | K19: 12.2 | L19: 12.2 | M19: 12.2 | N19: 12.2 | O19: 12.2 | P19: 12.2 | Q19: 12.2 | R19: 12.2 | S19: 12.2 | T19: 12.2 | U19: 12.2 | V19: 12.2 | W19: 12.2 | X19: 12.2 | Y19: 12.2 | Z19: 12.2 | AA19: 12.2 | AB19: 12.2 | AC19: 12.2 | AD19: 12.2 | AE19: 12.2 | AF19: 12.2 | AG19: 38.46 | AH19: =MAX(B19:AF19) -> 12.2 | AI19: =MIN(B19:AF19) -> 12.2
A20: Upper Kalanga Gad(38.46) | B20: 7.8 | C20: 7.8 | D20: 7.8 | E20: 7.8 | F20: 7.8 | G20: 7.8 | H20: 7.8 | I20: 7.8 | J20: 7.8 | K20: 7.8 | L20: 7.8 | M20: 7.8 | N20: 7.8 | O20: 7.8 | P20: 7.8 | Q20: 7.8 | R20: 7.8 | S20: 7.8 | T20: 7.8 | U20: 7.8 | V20: 7.8 | W20: 7.8 | X20: 7.8 | Y20: 7.8 | Z20: 7.8 | AA20: 7.8 | AB20: 7.8 | AC20: 7.8 | AD20: 7.8 | AE20: 7.8 | AF20: 7.8 | AG20: 38.46 | AH20: =MAX(B20:AF20) -> 7.8 | AI20: =MIN(B20:AF20) -> 7.8
A21: Upper Balefi (36) | B21: 13 | C21: 13 | D21: 13 | E21: 13 | F21: 13 | G21: 13 | H21: 13 | I21: 13 | J21: 13 | K21: 13 | L21: 13 | M21: 13 | N21: 13 | O21: 13 | P21: 13 | Q21: 13 | R21: 13 | S21: 13 | T21: 13 | U21: 13 | V21: 13 | W21: 13 | X21: 13 | Y21: 13 | Z21: 13 | AA21: 13 | AB21: 13 | AC21: 13 | AD21: 13 | AE21: 13 | AF21: 13 | AG21: 36 | AH21: =MAX(B21:AF21) -> 13 | AI21: =MIN(B21:AF21) -> 13
A22: Nyadi(30) | B22: 8.8 | C22: 8.8 | D22: 8.8 | E22: 8.8 | F22: 8.8 | G22: 8.8 | H22: 8.8 | I22: 8.8 | J22: 8.8 | K22: 8.8 | L22: 8.8 | M22: 8.8 | N22: 8.8 | O22: 8.8 | P22: 8.8 | Q22: 8.8 | R22: 8.8 | S22: 8.8 | T22: 8.8 | U22: 8.8 | V22: 8.8 | W22: 8.8 | X22: 8.8 | Y22: 8.8 | Z22: 8.8 | AA22: 8.8 | AB22: 8.8 | AC22: 8.8 | AD22: 8.8 | AE22: 8.8 | AF22: 8.8 | AG22: 30 | AH22: =MAX(B22:AF22) -> 8.8 | AI22: =MIN(B22:AF22) -> 8.8
A23: Likhu Khola A(29.04) | B23: 9 | C23: 9 | D23: 9 | E23: 9 | F23: 9 | G23: 9 | H23: 9 | I23: 9 | J23: 9 | K23: 9 | L23: 9 | M23: 9 | N23: 9 | O23: 9 | P23: 9 | Q23: 9 | R23: 9 | S23: 9 | T23: 9 | U23: 9 | V23: 9 | W23: 9 | X23: 9 | Y23: 9 | Z23: 9 | AA23: 9 | AB23: 9 | AC23: 9 | AD23: 9 | AE23: 9 | AF23: 9 | AG23: 24.2 | AH23: =MAX(B23:AF23) -> 9 | AI23: =MIN(B23:AF23) -> 9
A24: Lower Likhu(28) | B24: 7.2 | C24: 7.2 | D24: 7.2 | E24: 7.2 | F24: 7.2 | G24: 7.2 | H24: 7.2 | I24: 7.2 | J24: 7.2 | K24: 7.2 | L24: 7.2 | M24: 7.2 | N24: 7.2 | O24: 7.2 | P24: 7.2 | Q24: 7.2 | R24: 7.2 | S24: 7.2 | T24: 7.2 | U24: 7.2 | V24: 7.2 | W24: 7.2 | X24: 7.2 | Y24: 7.2 | Z24: 7.2 | AA24: 7.2 | AB24: 7.2 | AC24: 7.2 | AD24: 7.2 | AE24: 7.2 | AF24: 7.2 | AG24: 28 | AH24: =MAX(B24:AF24) -> 7.2 | AI24: =MIN(B24:AF24) -> 7.2
A25: Dordi(27) | B25: 6.7 | C25: 6.7 | D25: 6.7 | E25: 6.7 | F25: 6.7 | G25: 6.7 | H25: 6.7 | I25: 6.7 | J25: 6.7 | K25: 6.7 | L25: 6.7 | M25: 6.7 | N25: 6.7 | O25: 6.7 | P25: 6.7 | Q25: 6.7 | R25: 6.7 | S25: 6.7 | T25: 6.7 | U25: 6.7 | V25: 6.7 | W25: 6.7 | X25: 6.7 | Y25: 6.7 | Z25: 6.7 | AA25: 6.7 | AB25: 6.7 | AC25: 6.7 | AD25: 6.7 | AE25: 6.7 | AF25: 6.7 | AG25: 30 | AH25: =MAX(B25:AF25) -> 6.7 | AI25: =MIN(B25:AF25) -> 6.7
A26: Upper Madi(25) | B26: 8.2 | C26: 8.2 | D26: 8.2 | E26: 8.2 | F26: 8.2 | G26: 8.2 | H26: 8.2 | I26: 8.2 | J26: 8.2 | K26: 8.2 | L26: 8.2 | M26: 8.2 | N26: 8.2 | O26: 8.2 | P26: 8.2 | Q26: 8.2 | R26: 8.2 | S26: 8.2 | T26: 8.2 | U26: 8.2 | V26: 8.2 | W26: 8.2 | X26: 8.2 | Y26: 8.2 | Z26: 8.2 | AA26: 8.2 | AB26: 8.2 | AC26: 8.2 | AD26: 8.2 | AE26: 8.2 | AF26: 8.2 | AG26: 25 | AH26: =MAX(B26:AF26) -> 8.2 | AI26: =MIN(B26:AF26) -> 8.2
A27: Kabeli B-1(25) | B27: 5 | C27: 5 | D27: 5 | E27: 5 | F27: 5 | G27: 5 | H27: 5 | I27: 5 | J27: 5 | K27: 5 | L27: 5 | M27: 5 | N27: 5 | O27: 5 | P27: 5 | Q27: 5 | R27: 5 | S27: 5 | T27: 5 | U27: 5 | V27: 5 | W27: 5 | X27: 5 | Y27: 5 | Z27: 5 | AA27: 5 | AB27: 5 | AC27: 5 | AD27: 5 | AE27: 5 | AF27: 5 | AG27: 25 | AH27: =MAX(B27:AF27) -> 5 | AI27: =MIN(B27:AF27) -> 5
A28: Singati Khola(25) | B28: 6 | C28: 6 | D28: 6 | E28: 6 | F28: 6 | G28: 6 | H28: 6 | I28: 6 | J28: 6 | K28: 6 | L28: 6 | M28: 6 | N28: 6 | O28: 6 | P28: 6 | Q28: 6 | R28: 6 | S28: 6 | T28: 6 | U28: 6 | V28: 6 | W28: 6 | X28: 6 | Y28: 6 | Z28: 6 | AA28: 6 | AB28: 6 | AC28: 6 | AD28: 6 | AE28: 6 | AF28: 6 | AG28: 25 | AH28: =MAX(B28:AF28) -> 6 | AI28: =MIN(B28:AF28) -> 6
A29: Upper Dordi (25) | B29: 7.4 | C29: 7.4 | D29: 7.4 | E29: 7.4 | F29: 7.4 | G29: 7.4 | H29: 7.4 | I29: 7.4 | J29: 7.4 | K29: 7.4 | L29: 7.4 | M29: 7.4 | N29: 7.4 | O29: 7.4 | P29: 7.4 | Q29: 7.4 | R29: 7.4 | S29: 7.4 | T29: 7.4 | U29: 7.4 | V29: 7.4 | W29: 7.4 | X29: 7.4 | Y29: 7.4 | Z29: 7.4 | AA29: 7.4 | AB29: 7.4 | AC29: 7.4 | AD29: 7.4 | AE29: 7.4 | AF29: 7.4 | AG29: 25 | AH29: =MAX(B29:AF29) -> 7.4 | AI29: =MIN(B29:AF29) -> 7.4
... A56: Other IPP Total | B56: 150 | C56: 150 | D56: 150 | E56: 150 | F56: 150 | G56: 150 | H56: 150 | I56: 150 | J56: 150 | K56: 150 | L56: 150 | M56: 150 | N56: 150 | O56: 150 | P56: 150 | Q56: 150 | R56: 150 | S56: 150 | T56: 150 | U56: 150 | V56: 150 | W56: 150 | X56: 150 | Y56: 150 | Z56: 150 | AA56: 150 | AB56: 150 | AC56: 150 | AD56: 150 | AE56: 150 | AF56: 150 | AG56: 85 | AH56: =MAX(B56:AF56) -> 150 | AI56: =MIN(B56:AF56) -> 150
A57: Kabeli Corridor | B57: 26.3 | C57: 26.3 | D57: 26.3 | E57: 27.1 | F57: 24.3 | G57: 24.3 | H57: 24.3 | I57: 24.3 | J57: 21.5 | K57: 21.5 | L57: 21.5 | M57: 14.2 | N57: =14.1+5.9 -> 20 | O57: =16.1+6.6 -> 22.7 | P57: =16.6+7.2 -> 23.8 | Q57: =18.2+9.5 -> 27.7 | R57: =14.6+4.5 -> 19.1 | S57: 16.5 | T57: 16.5 | U57: 19.7 | V57: 17.1 | W57: 17.1 | X57: 15 | Y57: 15 | Z57: 15 | AA57: 15 | AB57: 15 | AC57: 15 | AD57: 15 | AE57: 15 | AF57: 15 | AG57: 240 | AH57: =MAX(B57:AF57) -> 27.7 | AI57: =MIN(B57:AF57) -> 14.2
A58: Total IPP | B58: =SUM(B11:B56) -> 484.25 | C58: =SUM(C11:C56) -> 484.25 | D58: =SUM(D11:D56) -> 484.25 | E58: =SUM(E11:E56) -> 483.25 | F58: =SUM(F11:F56) -> 482.75 | G58: =SUM(G11:G56) -> 482.25 | H58: =SUM(H11:H56) -> 482.25 | I58: =SUM(I11:I56) -> 482.25 | ... AF58: =SUM(AF11:AF56) -> 481.65 | AG58: =SUM(AG14:AG56) -> 1042.4 | AH58: =MAX(B58:AF58) -> 484.25 | AI58: =MIN(B58:AF58) -> 468.35
A59: Upper Tamakoshi(456) | B59: 0 | C59: 0 | D59: 0 | E59: 0 | F59: 0 | G59: 0 | H59: 0 | I59: 0 | J59: 100 | K59: 270 | L59: 400 | M59: 420 | N59: 260 | O59: 140 | P59: 15 | Q59: 35 | R59: 15 | S59: 20 | T59: 0 | U59: 0 | V59: 15 | W59: 30 | X59: 230 | Y59: 300 | Z59: 340 | AA59: 320 | AB59: 230 | AC59: 230 | AD59: 40 | AE59: 0 | AF59: 0 | AG59: 456 | AH59: =MAX(B59:AF59) -> 420 | AI59: =MIN(B59:AF59) -> 0
A60: Khimti Khola(60) | B60: 30 | C60: 30 | D60: 30 | E60: 30 | F60: 30 | G60: 30 | H60: 30 | I60: 30 | J60: 30 | K60: 30 | L60: 30 | M60: 30 | N60: 30 | O60: 30 | P60: 30 | Q60: 30 | R60: 30 | S60: 30 | T60: 30 | U60: 30 | V60: 30 | W60: 30 | X60: 30 | Y60: 30 | Z60: 30 | AA60: 30 | AB60: 30 | AC60: 30 | AD60: 30 | AE60: 30 | AF60: 30 | AG60: 60 | AH60: =MAX(B60:AF60) -> 30 | AI60: =MIN(B60:AF60) -> 30
A61: Chilime(22.1) | B61: 10 | C61: 10 | D61: 10 | E61: 10 | F61: 10.2 | G61: 10.2 | H61: 10.2 | I61: 10.2 | J61: 10.2 | K61: 10.3 | L61: 10.3 | M61: 10.2 | N61: 10.2 | O61: 10.2 | P61: 10.2 | Q61: 10.2 | R61: 10.2 | S61: 10.2 | T61: 10.2 | U61: 10.2 | V61: 10.2 | W61: 10.2 | X61: 10.2 | Y61: 10.2 | Z61: 10.2 | AA61: 10.2 | AB61: 10.2 | AC61: 10.2 | AD61: 10.2 | AE61: 10.2 | AF61: 10.2 | AG61: 22.1 | AH61: =MAX(B61:AF61) -> 10.3 | AI61: =MIN(B61:AF61) -> 10
A62: Total NEA SUBSIDIARIES | B62: =SUM(B59:B61) -> 40 | C62: =SUM(C59:C61) -> 40 | D62: =SUM(D59:D61) -> 40 | E62: =SUM(E59:E61) -> 40 | F62: =SUM(F59:F61) -> 40.2 | G62: =SUM(G59:G61) -> 40.2 | H62: =SUM(H59:H61) -> 40.2 | I62: =SUM(I59:I61) -> 40.2 | ... AG62: =SUM(AG59:AG61) -> 538.1 | AH62: =MAX(B62:AF62) -> 460.2 | AI62: =MIN(B62:AF62) -> 40
A63: KGA(144) | B63: 0 | C63: 0 | D63: 0 | E63: 0 | F63: 0 | G63: 30 | H63: 96 | I63: 96 | J63: 111.4 | K63: 140 | L63: 133.7 | M63: 144.1 | N63: 60.9 | O63: 60.9 | P63: 30 | Q63: 48 | R63: 49 | S63: 49 | T63: 43 | U63: 43 | V63: 62.2 | W63: 62.2 | X63: 98 | Y63: 130 | Z63: 130 | AA63: 134 | AB63: 91.1 | AC63: 80.1 | AD63: 61.1 | AE63: 48.7 | AF63: 30.6 | AG63: 144 | AH63: =MAX(B63:AF63) -> 144.1 | AI63: =MIN(B63:AF63) -> 0
A64: Middle MRS(70) | B64: 0 | C64: 0 | D64: 0 | E64: 0 | F64: 0 | G64: 16 | H64: 35 | I64: 50 | J64: 51.4 | K64: 65 | L64: 65 | M64: 65 | N64: 43 | O64: 43 | P64: 43 | Q64: 35 | R64: 35 | S64: 35 | T64: 25 | U64: 25 | V64: 25 | W64: 25 | X64: 69 | Y64: 60 | Z64: 60 | AA64: 45 | AB64: 35 | AC64: 25 | AD64: 25 | AE64: 25 | AF64: 25 | AG64: 70 | AH64: =MAX(B64:AF64) -> 69 | AI64: =MIN(B64:AF64) -> 0
A65: MRS(69) | B65: 0 | C65: 0 | D65: 0 | E65: 0 | F65: 0 | G65: 25 | H65: 34.3 | I65: 34.3 | J65: 68.3 | K65: 55.9 | L65: 69 | M65: 64 | N65: 53.6 | O65: 53.6 | P65: 33.8 | Q65: 33.7 | R65: 39.3 | S65: 34 | T65: 34 | U65: 34 | V65: 34 | W65: 34 | X65: 69 | Y65: 68 | Z65: 68 | AA65: 68 | AB65: 67.1 | AC65: 48.1 | AD65: 48.9 | AE65: 49.2 | AF65: 0 | AG65: 69 | AH65: =MAX(B65:AF65) -> 69 | AI65: =MIN(B65:AF65) -> 0
A66: U Trisuli 3A(60) | B66: 38 | C66: 38 | D66: 38 | E66: 39.3 | F66: 39.3 | G66: 39.3 | H66: 39 | I66: 39 | J66: 39.32 | K66: 39.32 | L66: 41.1 | M66: 41.2 | N66: 38.8 | O66: 38.8 | P66: 39.3 | Q66: 40.3 | R66: 40.3 | S66: 40.3 | T66: 38.5 | U66: 38.5 | V66: 38.5 | W66: 38.5 | X66: 38.5 | Y66: 38 | Z66: 38 | AA66: 38 | AB66: 38 | AC66: 38 | AD66: 38 | AE66: 41.3 | AF66: 41.3 | AG66: 60 | AH66: =MAX(B66:AF66) -> 41.3 | AI66: =MIN(B66:AF66) -> 38
A67: CHM(30) | B67: 0 | C67: 0 | D67: 0 | E67: 0 | F67: 12 | G67: 12 | H67: 12 | I67: 12 | J67: 15 | K67: 23 | L67: 29 | M67: 28.8 | N67: 10 | O67: 0 | P67: 0 | Q67: 10 | R67: 10 | S67: 10 | T67: 10 | U67: 10 | V67: 10 | W67: 0 | X67: 10 | Y67: 15 | Z67: 23 | AA67: 23 | AB67: 28 | AC67: 28 | AD67: 10 | AE67: 0 | AF67: 0 | AG67: 30 | AH67: =MAX(B67:AF67) -> 29 | AI67: =MIN(B67:AF67) -> 0 | AZ67: 1 | BA67: 2 | BB67: 3 | BC67: 4 | BD67: 5 | BE67: 6 | BF67: 7 | BG67: 8 | BH67: 9 | BI67: 10 | BJ67: 11 | BK67: 12 | BL67: 13 | BM67: 14 | BN67: 15 | BO67: 16 | BP67: 17 | BQ67: 18 | BR67: 19 | BS67: 20 | BT67: 21 | BU67: 22 | BV67: 23 | BW67: 24
...

Sheet 2
A1: LOAD DISPATCH CENTRE, NEPAL ELECTRICITY AUTHORITY DAILY SYSTEM OPERATION LOG FOR INPS | AG1: Installed Capacity (MW)
B2: Bhai | D2: Sim | F2: Ktm | H2: Brt | J2: Rainfall | K2: Bhai | L2: Sim | M2: Ktm | N2: Brt | AG2: =AG58 -> 1042.4 | AH2: IPP
V3: * other ipp reduced to 210 due to addition of rudi khola a in log sheet | X3: llkkjmj | AG3: =AG76 -> 489.91 | AH3: NEA RoR
A4: Nepali Date: | B4: ="2080/"&"10/"&INT(MID(CELL("filename",D6),FIND("]",CELL("filename",D6))+1,200)) -> 2080/10/2 | E4: ="2080/"&"10/"&INT(MID(CELL("filename",G6),FIND("]",CELL("filename",G6))+1,200)) -> 2080/10/2 | H4: =TEXT(E4,"dddd") -> Wednesday | K4: ="Total Peak Supply(Inclusive of Export) ("&ROUND(B264,0)&" MW)"&" IPP = "&ROUND(B259,0)&" MW NEA RoR = "&ROUND(B260,0)&" MWImport = "&ROUND(B262,0)&" MW KL1+KL2+K3 = "&ROUND(B261,0) &" MW EXPORT = "&ROUND(B263,0) -> Total Peak Supply(Inclusive of Export) (0 MW) IPP = 0 MW NEA RoR = 0 MWImport = 0 MW KL1+KL2+K3 = 0 MW EXPORT = 0 | AG4: =AG80 -> 106 | AH4: NEA Storage
B5: =C92 -> 590.1 | C5: =D92 -> 546.7 | D5: =E92 -> 547.3 | E5: =F92 -> 566.3 | F5: =G92 -> 624.9 | G5: =H92 -> 609.2 | H5: =I92 -> 635 | I5: =J92 -> 595.3 | ... AE5: =AF92 -> 663.1 | AF5: =B92 -> 555.6
K6: ="Evening Peak "&ROUND(B264,0)&"MW at "&TRUNC(B265*24,0)&":"&ROUND((B265*24-TRUNC(B265*24,0))*60,0)&"hr at "&ROUND(B266,1)&"Hz "&A256&" "&ROUND(B256,0)&"MW at "&TRUNC(C256*24,0)&":"&ROUND((C256*24-TRUNC(C256*24,0))*6,0)&"0hr" -> Evening Peak 0MW at 0:0hr at 0Hz Morning Peak 1796MW at 7:30hr | AG6: =SUM(AG2:AG4) -> 1638.31 | AH6: Total Hydro
A7: ="Base Load="&ROUND(MIN($B$7:$AF$7),0) -> Base Load=1150 | B7: =B100 -> 1190.79 | C7: =C100 -> 1194.69 | D7: =D100 -> 1151.29 | E7: =E100 -> 1149.89 | F7: =F100 -> 1168.69 | G7: =G100 -> 1266.59 | H7: =H100 -> 1340.39 | I7: =I100 -> 1433.79 | ... AF7: =AF100 -> 1268.99
B8: Night Shift(Contd..) | M8: Morning Shift | S8: Day Shift | AB8: Night Shift
A9: Hrs. Source | B9: 0 | C9: 0.041666667 | D9: 0.083333333 | E9: 0.125 | F9: 0.16666667 | G9: 0.20833333 | H9: 0.22916667 | I9: 0.25 | J9: 0.27083333 | K9: 0.29166667 | L9: 0.3125 | M9: 0.33333333 | N9: 0.375 | O9: 0.41666667 | P9: 0.45833333 | Q9: 0.5 | R9: 0.54166667 | S9: 0.58333333 | T9: 0.625 | U9: 0.66666667 | V9: 0.70833333 | W9: 0.72916667 | X9: 0.75 | Y9: 0.77083333 | Z9: 0.79166667 | AA9: 0.8125 | AB9: 0.83333333 | AC9: 0.85416667 | AD9: 0.875 | AE9: 0.91666667 | AF9: 0.95833333 | AG9: Installed Capacity (MW)
A11: Solu Khola Dudhkoshi(86) | B11: 28.3 | C11: 28.3 | D11: 28.3 | E11: 28.3 | F11: 28.3 | G11: 28.3 | H11: 28.3 | I11: 28.3 | J11: 28.3 | K11: 28.3 | L11: 28.3 | M11: 28.3 | N11: 28.3 | O11: 28.3 | P11: 28.3 | Q11: 28.3 | R11: 28.3 | S11: 28.3 | T11: 28.3 | U11: 28.3 | V11: 28.3 | W11: 28.3 | X11: 28 | Y11: 28 | Z11: 28 | AA11: 28 | AB11: 28.4 | AC11: 29.1 | AD11: 29.1 | AE11: 29.1 | AF11: 29.8 | AG11: 86 | AH11: =MAX(B11:AF11) -> 29.8 | AI11: =MIN(B11:AF11) -> 28
A12: Likhu-II(55) | B12: 9.8 | C12: 9.8 | D12: 9.8 | E12: 9.8 | F12: 9.8 | G12: 9.8 | H12: 9.8 | I12: 9.8 | J12: 9.8 | K12: 9.8 | L12: 9.8 | M12: 9.8 | N12: 9.8 | O12: 9.8 | P12: 9.8 | Q12: 9.8 | R12: 9.8 | S12: 9.8 | T12: 9.8 | U12: 9.8 | V12: 9.8 | W12: 9.8 | X12: 9.8 | Y12: 9.8 | Z12: 9.8 | AA12: 9.8 | AB12: 9.8 | AC12: 9.8 | AD12: 9.8 | AE12: 9.8 | AF12: 9.8 | AG12: 54 | AH12: =MAX(B12:AF12) -> 9.8 | AI12: =MIN(B12:AF12) -> 9.8
A13: Super Dordi (54) | B13: 10.3 | C13: 10.3 | D13: 10.3 | E13: 10.3 | F13: 10.3 | G13: 10.3 | H13: 10.3 | I13: 10.3 | J13: 10.3 | K13: 10.3 | L13: 10.3 | M13: 10.3 | N13: 10.3 | O13: 10.3 | P13: 10.3 | Q13: 10.3 | R13: 10.3 | S13: 10.3 | T13: 10.3 | U13: 10.3 | V13: 10.3 | W13: 10.3 | X13: 10.3 | Y13: 10.3 | Z13: 10.3 | AA13: 10.3 | AB13: 10.3 | AC13: 10.3 | AD13: 10.3 | AE13: 10.3 | AF13: 10.3 | AG13: 54 | AH13: =MAX(B13:AF13) -> 10.3 | AI13: =MIN(B13:AF13) -> 10.3
A14: Likhu-IV(52.4) | B14: 15.3 | C14: 15.3 | D14: 15.3 | E14: 15.3 | F14: 15.3 | G14: 15.3 | H14: 15.3 | I14: 15.3 | J14: 15.3 | K14: 15.3 | L14: 15.3 | M14: 15.3 | N14: 15.3 | O14: 15.3 | P14: 15.3 | Q14: 15.3 | R14: 15.3 | S14: 15.3 | T14: 15.3 | U14: 15.3 | V14: 15.3 | W14: 15.3 | X14: 15.3 | Y14: 15.3 | Z14: 15.3 | AA14: 15.3 | AB14: 15.3 | AC14: 15.3 | AD14: 15.3 | AE14: 16.5 | AF14: 16.5 | AG14: 52.4 | AH14: =MAX(B14:AF14) -> 16.5 | AI14: =MIN(B14:AF14) -> 15.3
A15: Upper Marsyangdi "A"(50) | B15: 29.1 | C15: 29.1 | D15: 29.1 | E15: 29.1 | F15: 29.1 | G15: 29.1 | H15: 29.1 | I15: 29.1 | J15: 29.1 | K15: 29.1 | L15: 29.1 | M15: 29.1 | N15: 29.1 | O15: 29.1 | P15: 29.1 | Q15: 29.1 | R15: 29.1 | S15: 29.1 | T15: 29.1 | U15: 29.1 | V15: 29.1 | W15: 29.1 | X15: 29.1 | Y15: 29.1 | Z15: 29.1 | AA15: 29.1 | AB15: 29.1 | AC15: 29.1 | AD15: 29.1 | AE15: 29.1 | AF15: 29.1 | AG15: 50 | AH15: =MAX(B15:AF15) -> 29.1 | AI15: =MIN(B15:AF15) -> 29.1
A16: Upper Bhotekoshi Khola(45) | B16: 16.6 | C16: 16.6 | D16: 16.6 | E16: 16.6 | F16: 16.6 | G16: 16.6 | H16: 16.6 | I16: 16.6 | J16: 16.6 | K16: 16.6 | L16: 16.6 | M16: 16.6 | N16: 16.6 | O16: 16.6 | P16: 16.6 | Q16: 16.6 | R16: 16.6 | S16: 16.6 | T16: 16.6 | U16: 16.6 | V16: 16.6 | W16: 16.6 | X16: 16.6 | Y16: 16.6 | Z16: 16.6 | AA16: 16.6 | AB16: 16.6 | AC16: 16.6 | AD16: 16.6 | AE16: 17.3 | AF16: 17.3 | AG16: 45 | AH16: =MAX(B16:AF16) -> 17.3 | AI16: =MIN(B16:AF16) -> 16.6
A17: Super Madi ( 44 ) | B17: 14 | C17: 14 | D17: 14 | E17: 14 | F17: 14 | G17: 14 | H17: 14 | I17: 14 | J17: 14 | K17: 14 | L17: 14 | M17: 14 | N17: 14 | O17: 14 | P17: 14 | Q17: 14 | R17: 14 | S17: 14 | T17: 14 | U17: 14 | V17: 14 | W17: 14 | X17: 14 | Y17: 14 | Z17: 14 | AA17: 14 | AB17: 14 | AC17: 14 | AD17: 14 | AE17: 14 | AF17: 14 | AG17: 44 | AH17: =MAX(B17:AG17) -> 44 | AI17: =MIN(B17:AG17) -> 14
A18: Mistri Khola(42) | B18: 8 | C18: 8 | D18: 8 | E18: 8 | F18: 8 | G18: 8 | H18: 8 | I18: 8 | J18: 8 | K18: 8 | L18: 8 | M18: 8 | N18: 8 | O18: 8 | P18: 8 | Q18: 8 | R18: 8 | S18: 8 | T18: 8 | U18: 8 | V18: 8 | W18: 8 | X18: 7 | Y18: 7 | Z18: 7 | AA18: 7 | AB18: 7 | AC18: 7 | AD18: 7 | AE18: 7 | AF18: 7 | AG18: 42 | AH18: =MAX(B18:AF18) -> 8 | AI18: =MIN(B18:AF18) -> 7
A19: Upper Chameliya(40) | B19: 12.2 | C19: 12.2 | D19: 12.2 | E19: 12.2 | F19: 12.2 | G19: 12.2 | H19: 12.2 | I19: 12.2 | J19: 12.2 | K19: 12.2 | L19: 12.2 | M19: 12.2 | N19: 12.2 | O19: 12.2 | P19: 12.2 | Q19: 12.2 | R19: 12.2 | S19: 12.2 | T19: 12.2 | U19: 12.2 | V19: 12.2 | W19: 12.2 | X19: 12.2 | Y19: 12.2 | Z19: 12.2 | AA19: 12.2 | AB19: 12.2 | AC19: 12.2 | AD19: 12.2 | AE19: 12.2 | AF19: 12.2 | AG19: 38.46 | AH19: =MAX(B19:AF19) -> 12.2 | AI19: =MIN(B19:AF19) -> 12.2
A20: Upper Kalanga Gad(38.46) | B20: 7.8 | C20: 7.8 | D20: 7.8 | E20: 7.8 | F20: 7.8 | G20: 7.8 | H20: 7.8 | I20: 7.8 | J20: 7.8 | K20: 7.8 | L20: 7.8 | M20: 7.8 | N20: 7.8 | O20: 7.8 | P20: 7.8 | Q20: 7.8 | R20: 7.8 | S20: 7.8 | T20: 7.8 | U20: 7.8 | V20: 7.8 | W20: 7.8 | X20: 7.8 | Y20: 7.8 | Z20: 7.8 | AA20: 7.8 | AB20: 7.8 | AC20: 7.8 | AD20: 7.8 | AE20: 7.8 | AF20: 7.8 | AG20: 38.46 | AH20: =MAX(B20:AF20) -> 7.8 | AI20: =MIN(B20:AF20) -> 7.8
A21: Upper Balefi (36) | B21: 13 | C21: 13 | D21: 13 | E21: 13 | F21: 13 | G21: 13 | H21: 13 | I21: 13 | J21: 13 | K21: 13 | L21: 13 | M21: 13 | N21: 13 | O21: 13 | P21: 13 | Q21: 13 | R21: 13 | S21: 13 | T21: 13 | U21: 13 | V21: 13 | W21: 13 | X21: 13 | Y21: 13 | Z21: 13 | AA21: 13 | AB21: 13 | AC21: 13 | AD21: 13 | AE21: 13 | AF21: 13 | AG21: 36 | AH21: =MAX(B21:AF21) -> 13 | AI21: =MIN(B21:AF21) -> 13
A22: Nyadi(30) | B22: 8.8 | C22: 8.8 | D22: 8.8 | E22: 8.8 | F22: 8.8 | G22: 8.8 | H22: 8.8 | I22: 8.8 | J22: 8.8 | K22: 8.8 | L22: 8.8 | M22: 8.8 | N22: 8.8 | O22: 8.8 | P22: 8.8 | Q22: 8.8 | R22: 8.8 | S22: 8.8 | T22: 8.8 | U22: 8.8 | V22: 8.8 | W22: 8.8 | X22: 7.8 | Y22: 7.8 | Z22: 7.8 | AA22: 7.8 | AB22: 7.8 | AC22: 7.8 | AD22: 7.8 | AE22: 7.8 | AF22: 7.8 | AG22: 30 | AH22: =MAX(B22:AF22) -> 8.8 | AI22: =MIN(B22:AF22) -> 7.8
A23: Likhu Khola A(29.04) | B23: 9 | C23: 9 | D23: 9 | E23: 9 | F23: 9 | G23: 9 | H23: 9 | I23: 9 | J23: 9 | K23: 9 | L23: 9 | M23: 9 | N23: 9 | O23: 9 | P23: 9 | Q23: 9 | R23: 9 | S23: 9 | T23: 9 | U23: 9 | V23: 9 | W23: 9 | X23: 9 | Y23: 9 | Z23: 9 | AA23: 9 | AB23: 9 | AC23: 9 | AD23: 9 | AE23: 9 | AF23: 9 | AG23: 24.2 | AH23: =MAX(B23:AF23) -> 9 | AI23: =MIN(B23:AF23) -> 9
A24: Lower Likhu(28) | B24: 7.2 | C24: 7.2 | D24: 7.2 | E24: 7.2 | F24: 7.2 | G24: 7.2 | H24: 7.2 | I24: 7.2 | J24: 7.2 | K24: 7.2 | L24: 7.2 | M24: 7.2 | N24: 7.2 | O24: 7.2 | P24: 7.2 | Q24: 7.2 | R24: 7.2 | S24: 7.2 | T24: 7.2 | U24: 7.2 | V24: 7.2 | W24: 7.2 | X24: 7.2 | Y24: 7.2 | Z24: 7.2 | AA24: 7.2 | AB24: 7.2 | AC24: 7.2 | AD24: 7.2 | AE24: 8.7 | AF24: 8.7 | AG24: 28 | AH24: =MAX(B24:AF24) -> 8.7 | AI24: =MIN(B24:AF24) -> 7.2
A25: Dordi(27) | B25: 6.7 | C25: 6.7 | D25: 6.7 | E25: 6.7 | F25: 6.7 | G25: 6.7 | H25: 6.7 | I25: 6.7 | J25: 6.7 | K25: 6.7 | L25: 6.7 | M25: 6.7 | N25: 6.7 | O25: 6.7 | P25: 6.7 | Q25: 6.7 | R25: 6.7 | S25: 6.7 | T25: 6.7 | U25: 6.7 | V25: 6.7 | W25: 6.7 | X25: 7 | Y25: 7 | Z25: 7 | AA25: 7 | AB25: 7 | AC25: 7 | AD25: 7 | AE25: 6.4 | AF25: 6.4 | AG25: 30 | AH25: =MAX(B25:AF25) -> 7 | AI25: =MIN(B25:AF25) -> 6.4
A26: Upper Madi(25) | B26: 8.2 | C26: 8.2 | D26: 8.2 | E26: 8.2 | F26: 8.2 | G26: 8.2 | H26: 8.2 | I26: 8.2 | J26: 8.2 | K26: 8.2 | L26: 8.2 | M26: 8.2 | N26: 8.2 | O26: 8.2 | P26: 8.2 | Q26: 8.2 | R26: 8.2 | S26: 8.2 | T26: 8.2 | U26: 8.2 | V26: 8.2 | W26: 8.2 | X26: 8.5 | Y26: 8.5 | Z26: 8.5 | AA26: 8.5 | AB26: 8.5 | AC26: 8.5 | AD26: 8.5 | AE26: 6.5 | AF26: 6.5 | AG26: 25 | AH26: =MAX(B26:AF26) -> 8.5 | AI26: =MIN(B26:AF26) -> 6.5
A27: Kabeli B-1(25) | B27: 5 | C27: 5 | D27: 5 | E27: 5 | F27: 5 | G27: 5 | H27: 5 | I27: 5 | J27: 5 | K27: 5 | L27: 5 | M27: 5 | N27: 5 | O27: 5 | P27: 5 | Q27: 5 | R27: 5 | S27: 5 | T27: 5 | U27: 5 | V27: 5 | W27: 5 | X27: 5 | Y27: 5 | Z27: 5 | AA27: 5 | AB27: 5 | AC27: 5 | AD27: 5 | AE27: 5 | AF27: 5 | AG27: 25 | AH27: =MAX(B27:AF27) -> 5 | AI27: =MIN(B27:AF27) -> 5
A28: Singati Khola(25) | B28: 6 | C28: 6 | D28: 6 | E28: 6 | F28: 6 | G28: 6 | H28: 6 | I28: 6 | J28: 6 | K28: 6 | L28: 6 | M28: 6 | N28: 6 | O28: 6 | P28: 6 | Q28: 6 | R28: 6 | S28: 6 | T28: 6 | U28: 6 | V28: 6 | W28: 6 | X28: 6 | Y28: 6 | Z28: 6 | AA28: 6 | AB28: 6 | AC28: 6 | AD28: 6 | AE28: 6 | AF28: 6 | AG28: 25 | AH28: =MAX(B28:AF28) -> 6 | AI28: =MIN(B28:AF28) -> 6
A29: Upper Dordi (25) | B29: 7.4 | C29: 7.4 | D29: 7.4 | E29: 7.4 | F29: 7.4 | G29: 7.4 | H29: 7.4 | I29: 7.4 | J29: 7.4 | K29: 7.4 | L29: 7.4 | M29: 7.4 | N29: 7.4 | O29: 7.4 | P29: 7.4 | Q29: 7.4 | R29: 7.4 | S29: 7.4 | T29: 7.4 | U29: 7.4 | V29: 7.4 | W29: 7.4 | X29: 7.4 | Y29: 7.4 | Z29: 7.4 | AA29: 7.4 | AB29: 7.4 | AC29: 7.4 | AD29: 7.4 | AE29: 7.2 | AF29: 7.2 | AG29: 25 | AH29: =MAX(B29:AF29) -> 7.4 | AI29: =MIN(B29:AF29) -> 7.2
... A56: Other IPP Total | B56: 150 | C56: 150 | D56: 150 | E56: 150 | F56: 150 | G56: 150 | H56: 150 | I56: 150 | J56: 150 | K56: 150 | L56: 150 | M56: 150 | N56: 150 | O56: 150 | P56: 150 | Q56: 150 | R56: 150 | S56: 150 | T56: 150 | U56: 150 | V56: 150 | W56: 150 | X56: 150 | Y56: 150 | Z56: 150 | AA56: 150 | AB56: 150 | AC56: 150 | AD56: 150 | AE56: 150 | AF56: 150 | AG56: 85 | AH56: =MAX(B56:AF56) -> 150 | AI56: =MIN(B56:AF56) -> 150
A57: Kabeli Corridor | B57: 15 | C57: 15 | D57: 15 | E57: =16.6+7.2 -> 23.8 | F57: =16.7+7 -> 23.7 | G57: =6.2+14.8 -> 21 | H57: =6.2+14.8 -> 21 | I57: =6.2+14.8 -> 21 | J57: =6.2+14.8 -> 21 | K57: =6.2+14.8 -> 21 | L57: =6.2+14.8 -> 21 | M57: =6.2+14.8 -> 21 | N57: =6.2+14.8 -> 21 | ... S57: =6.2+14.8 -> 21 | T57: 23.6 | U57: 23.6 | V57: 23 | W57: 21 | X57: 18.7 | Y57: 18.7 | Z57: 17 | AA57: 13.7 | AB57: =14.9+6.9 -> 21.8 | AC57: =14.9+6 -> 20.9 | AD57: =14.9+6.2 -> 21.1 | AE57: =6.6+15.4 -> 22 | AF57: =6.8+15.7 -> 22.5 | AG57: 240 | AH57: =MAX(B57:AF57) -> 23.8 | AI57: =MIN(B57:AF57) -> 13.7
A58: Total IPP | B58: =SUM(B11:B56) -> 481.65 | C58: =SUM(C11:C56) -> 481.65 | D58: =SUM(D11:D56) -> 481.65 | E58: =SUM(E11:E56) -> 481.65 | F58: =SUM(F11:F56) -> 481.65 | G58: =SUM(G11:G56) -> 481.65 | H58: =SUM(H11:H56) -> 481.65 | I58: =SUM(I11:I56) -> 481.65 | ... AF58: =SUM(AF11:AF56) -> 486.85 | AG58: =SUM(AG14:AG56) -> 1042.4 | AH58: =MAX(B58:AF58) -> 486.85 | AI58: =MIN(B58:AF58) -> 479.95
A59: Upper Tamakoshi(456) | B59: 0 | C59: 0 | D59: 0 | E59: 0 | F59: 0 | G59: 0 | H59: 15 | I59: 40 | J59: 150 | K59: 250 | L59: 210 | M59: 230 | N59: 140 | O59: 70 | P59: 76 | Q59: 76 | R59: 76 | S59: 36 | T59: 30 | U59: 30 | V59: 15 | W59: 60 | X59: 100 | Y59: 150 | Z59: 150 | AA59: 160 | AB59: 150 | AC59: 105 | AD59: 70 | AE59: 30 | AF59: 0 | AG59: 456 | AH59: =MAX(B59:AF59) -> 250 | AI59: =MIN(B59:AF59) -> 0
A60: Khimti Khola(60) | B60: 30 | C60: 30 | D60: 30 | E60: 30 | F60: 30 | G60: 30 | H60: 30 | I60: 30 | J60: 30 | K60: 30 | L60: 30 | M60: 30 | N60: 30 | O60: 30 | P60: 30 | Q60: 30 | R60: 30 | S60: 30 | T60: 30 | U60: 30 | V60: 30 | W60: 30 | X60: 30 | Y60: 30 | Z60: 30 | AA60: 30 | AB60: 30 | AC60: 30 | AD60: 30 | AE60: 30 | AF60: 30 | AG60: 60 | AH60: =MAX(B60:AF60) -> 30 | AI60: =MIN(B60:AF60) -> 30
A61: Chilime(22.1) | B61: 10.2 | C61: 10.2 | D61: 10.2 | E61: 10.2 | F61: 10.2 | G61: 10.2 | H61: 10.2 | I61: 10.2 | J61: 10.2 | K61: 10.2 | L61: 10.2 | M61: 10.2 | N61: 10.2 | O61: 10.2 | P61: 10.2 | Q61: 10.2 | R61: 10.2 | S61: 10.2 | T61: 10.2 | U61: 10.2 | V61: 10.2 | W61: 10.2 | X61: 10.2 | Y61: 10.2 | Z61: 10.2 | AA61: 10.2 | AB61: 10.2 | AC61: 10.2 | AD61: 10.2 | AE61: 10.2 | AF61: 10.2 | AG61: 22.1 | AH61: =MAX(B61:AF61) -> 10.2 | AI61: =MIN(B61:AF61) -> 10.2
A62: Total NEA SUBSIDIARIES | B62: =SUM(B59:B61) -> 40.2 | C62: =SUM(C59:C61) -> 40.2 | D62: =SUM(D59:D61) -> 40.2 | E62: =SUM(E59:E61) -> 40.2 | F62: =SUM(F59:F61) -> 40.2 | G62: =SUM(G59:G61) -> 40.2 | H62: =SUM(H59:H61) -> 55.2 | I62: =SUM(I59:I61) -> 80.2 | ... AG62: =SUM(AG59:AG61) -> 538.1 | AH62: =MAX(B62:AF62) -> 290.2 | AI62: =MIN(B62:AF62) -> 40.2
A63: KGA(144) | B63: 30.6 | C63: 0 | D63: 0 | E63: 0 | F63: 0 | G63: 30.6 | H63: 70 | I63: 70.7 | J63: 100 | K63: 112 | L63: 111.9 | M63: 111.4 | N63: 81.5 | O63: 80.8 | P63: 97.6 | Q63: 97 | R63: 97 | S63: 97.7 | T63: 86.2 | U63: 86.2 | V63: 60.8 | W63: 60.8 | X63: 60.8 | Y63: 60.8 | Z63: 71 | AA63: 61 | AB63: 60.7 | AC63: 60.5 | AD63: 30.5 | AE63: 0 | AF63: 0 | AG63: 144 | AH63: =MAX(B63:AF63) -> 112 | AI63: =MIN(B63:AF63) -> 0
A64: Middle MRS(70) | B64: 0 | C64: 0 | D64: 0 | E64: 0 | F64: 0 | G64: 0 | H64: 0 | I64: 32 | J64: 60 | K64: 60 | L64: 60 | M64: 60 | N64: 60 | O64: 35 | P64: 35 | Q64: 35 | R64: 35 | S64: 35 | T64: 35 | U64: 35 | V64: 25 | W64: 25 | X64: 50 | Y64: 65 | Z64: 65 | AA64: 35 | AB64: 25 | AC64: 25 | AD64: 25 | AE64: 0 | AF64: 0 | AG64: 70 | AH64: =MAX(B64:AF64) -> 65 | AI64: =MIN(B64:AF64) -> 0
A65: MRS(69) | B65: 0 | C65: 0 | D65: 0 | E65: 0 | F65: 0 | G65: 0 | H65: 35.6 | I65: 45.5 | J65: 68 | K65: 52.6 | L65: 60.5 | M65: 61.2 | N65: 61.2 | O65: 57.5 | P65: 44.4 | Q65: 20.7 | R65: 21.9 | S65: 22 | T65: 22 | U65: 22 | V65: 16.6 | W65: 16.6 | X65: 49.5 | Y65: 67.2 | Z65: 57 | AA65: 44 | AB65: 33 | AC65: 33 | AD65: 32.4 | AE65: 32.4 | AF65: 0 | AG65: 69 | AH65: =MAX(B65:AF65) -> 68 | AI65: =MIN(B65:AF65) -> 0
A66: U Trisuli 3A(60) | B66: 41.3 | C66: 41.3 | D66: 41.3 | E66: 39.3 | F66: 39.1 | G66: 37.8 | H66: 37.3 | I66: 37.3 | J66: 37.3 | K66: 37 | L66: 39.1 | M66: 39.1 | N66: 39.1 | O66: 39.8 | P66: 38.3 | Q66: 38.3 | R66: 38.3 | S66: 38.3 | T66: 38.3 | U66: 38.3 | V66: 38.3 | W66: 38.3 | X66: 38.3 | Y66: 38.3 | Z66: 38.3 | AA66: 38.3 | AB66: 38.3 | AC66: 37 | AD66: 37.3 | AE66: 39.1 | AF66: 39.1 | AG66: 60 | AH66: =MAX(B66:AF66) -> 41.3 | AI66: =MIN(B66:AF66) -> 37
A67: CHM(30) | B67: 0 | C67: 0 | D67: 0 | E67: 0 | F67: 0 | G67: 10 | H67: 10 | I67: 10 | J67: 15 | K67: 15 | L67: 15 | M67: 23 | N67: 23 | O67: 0 | P67: 0 | Q67: 0 | R67: 10 | S67: 10 | T67: 10 | U67: 10 | V67: 0 | W67: 0 | X67: 10 | Y67: 23 | Z67: 28 | AA67: 28 | AB67: 27.5 | AC67: 15 | AD67: 10 | AE67: 10 | AF67: 0 | AG67: 30 | AH67: =MAX(B67:AF67) -> 28 | AI67: =MIN(B67:AF67) -> 0
...

Sheet 3
A1: LOAD DISPATCH CENTRE, NEPAL ELECTRICITY AUTHORITY DAILY SYSTEM OPERATION LOG FOR INPS | AG1: Installed Capacity (MW)
B2: Bhai | D2: Sim | F2: Ktm | H2: Brt | J2: Rainfall | K2: Bhai | L2: Sim | M2: Ktm | N2: Brt | AG2: =AG58 -> 1042.4 | AH2: IPP
V3: * other ipp reduced to 210 due to addition of rudi khola a in log sheet | X3: llkkjmj | AG3: =AG76 -> 489.91 | AH3: NEA RoR
A4: Nepali Date: | B4: ="2080/"&"10/"&INT(MID(CELL("filename",D6),FIND("]",CELL("filename",D6))+1,200)) -> 2080/10/3 | E4: ="2080/"&"10/"&INT(MID(CELL("filename",G6),FIND("]",CELL("filename",G6))+1,200)) -> 2080/10/3 | H4: =TEXT(E4,"dddd") -> Thursday | K4: ="Total Peak Supply(Inclusive of Export) ("&ROUND(B264,0)&" MW)"&" IPP = "&ROUND(B259,0)&" MW NEA RoR = "&ROUND(B260,0)&" MWImport = "&ROUND(B262,0)&" MW KL1+KL2+K3 = "&ROUND(B261,0) &" MW EXPORT = "&ROUND(B263,0) -> Total Peak Supply(Inclusive of Export) (0 MW) IPP = 0 MW NEA RoR = 0 MWImport = 0 MW KL1+KL2+K3 = 0 MW EXPORT = 0 | AG4: =AG80 -> 106 | AH4: NEA Storage
B5: =C92 -> 566.6 | C5: =D92 -> 566.8 | D5: =E92 -> 553.78 | E5: =F92 -> 591.6 | F5: =G92 -> 564 | G5: =H92 -> 647.6 | H5: =I92 -> 657 | I5: =J92 -> 734 | ... AE5: =AF92 -> 579 | AF5: =B92 -> 675.4
K6: ="Evening Peak "&ROUND(B264,0)&"MW at "&TRUNC(B265*24,0)&":"&ROUND((B265*24-TRUNC(B265*24,0))*60,0)&"hr at "&ROUND(B266,1)&"Hz "&A256&" "&ROUND(B256,0)&"MW at "&TRUNC(C256*24,0)&":"&ROUND((C256*24-TRUNC(C256*24,0))*6,0)&"0hr" -> Evening Peak 0MW at 0:0hr at 0Hz Morning Peak 1852MW at 9:00hr | AG6: =SUM(AG2:AG4) -> 1638.31 | AH6: Total Hydro
A7: ="Base Load="&ROUND(MIN($B$7:$AF$7),0) -> Base Load=1155 | B7: =B100 -> 1281.49 | C7: =C100 -> 1172.69 | D7: =D100 -> 1166.79 | E7: =E100 -> 1155.17 | F7: =F100 -> 1192.99 | G7: =G100 -> 1181.29 | H7: =H100 -> 1281.79 | I7: =I100 -> 1368.09 | ... AF7: =AF100 -> 1249.39
B8: Night Shift(Contd..) | M8: Morning Shift | S8: Day Shift | AB8: Night Shift
A9: Hrs. Source | B9: 0 | C9: 0.041666667 | D9: 0.083333333 | E9: 0.125 | F9: 0.16666667 | G9: 0.20833333 | H9: 0.22916667 | I9: 0.25 | J9: 0.27083333 | K9: 0.29166667 | L9: 0.3125 | M9: 0.33333333 | N9: 0.375 | O9: 0.41666667 | P9: 0.45833333 | Q9: 0.5 | R9: 0.54166667 | S9: 0.58333333 | T9: 0.625 | U9: 0.66666667 | V9: 0.70833333 | W9: 0.72916667 | X9: 0.75 | Y9: 0.77083333 | Z9: 0.79166667 | AA9: 0.8125 | AB9: 0.83333333 | AC9: 0.85416667 | AD9: 0.875 | AE9: 0.91666667 | AF9: 0.95833333 | AG9: Installed Capacity (MW)
A11: Solu Khola Dudhkoshi(86) | B11: 29.5 | C11: 29.5 | D11: 29.5 | E11: 29.9 | F11: 29.9 | G11: 29.8 | H11: 29.8 | I11: 29.1 | J11: 28.4 | K11: 28.4 | L11: 28.4 | M11: 28.4 | N11: 28.4 | O11: 28.4 | P11: 28.4 | Q11: 28.4 | R11: 28.4 | S11: 28.8 | T11: 28.8 | U11: 29.8 | V11: 29.8 | W11: 29.8 | X11: 29.8 | Y11: 29.8 | Z11: 29.8 | AA11: 29.8 | AB11: 29.8 | AC11: 29.8 | AD11: 29.8 | AE11: 29.8 | AF11: 29.8 | AG11: 86 | AH11: =MAX(B11:AF11) -> 29.9 | AI11: =MIN(B11:AF11) -> 28.4
A12: Likhu-II(55) | B12: 9.8 | C12: 9.8 | D12: 9.8 | E12: 9.8 | F12: 9.8 | G12: 9.8 | H12: 9.8 | I12: 9.8 | J12: 9.8 | K12: 9.8 | L12: 9.8 | M12: 9.8 | N12: 9.8 | O12: 9.8 | P12: 9.8 | Q12: 9.8 | R12: 9.8 | S12: 9.8 | T12: 9.8 | U12: 9.8 | V12: 9.8 | W12: 9.8 | X12: 9.8 | Y12: 9.8 | Z12: 9.8 | AA12: 9.8 | AB12: 9.8 | AC12: 9.8 | AD12: 9.8 | AE12: 9.8 | AF12: 9.8 | AG12: 54 | AH12: =MAX(B12:AF12) -> 9.8 | AI12: =MIN(B12:AF12) -> 9.8
A13: Super Dordi (54) | B13: 10.3 | C13: 10.3 | D13: 10.3 | E13: 10.3 | F13: 10.3 | G13: 10.3 | H13: 10.3 | I13: 10.3 | J13: 10.3 | K13: 10.3 | L13: 10.3 | M13: 10.3 | N13: 10.3 | O13: 10.3 | P13: 10.3 | Q13: 10.3 | R13: 10.3 | S13: 10.3 | T13: 10.3 | U13: 10.3 | V13: 10.3 | W13: 10.3 | X13: 10.3 | Y13: 10.3 | Z13: 10.3 | AA13: 10.3 | AB13: 10.3 | AC13: 10.3 | AD13: 10.3 | AE13: 10.3 | AF13: 10.3 | AG13: 54 | AH13: =MAX(B13:AF13) -> 10.3 | AI13: =MIN(B13:AF13) -> 10.3
A14: Likhu-IV(52.4) | B14: 16.5 | C14: 16.5 | D14: 15.3 | E14: 15.3 | F14: 15.3 | G14: 15.3 | H14: 15.3 | I14: 15.3 | J14: 15.3 | K14: 15.3 | L14: 15.3 | M14: 15.3 | N14: 15.3 | O14: 15.3 | P14: 15.3 | Q14: 15.3 | R14: 15.3 | S14: 14.4 | T14: 17 | U14: 17 | V14: 17 | W14: 17 | X14: 17 | Y14: 17 | Z14: 17 | AA14: 17 | AB14: 17 | AC14: 17 | AD14: 17 | AE14: 17 | AF14: 17 | AG14: 52.4 | AH14: =MAX(B14:AF14) -> 17 | AI14: =MIN(B14:AF14) -> 14.4
A15: Upper Marsyangdi "A"(50) | B15: 29.1 | C15: 29.1 | D15: 28.3 | E15: 28.3 | F15: 28.3 | G15: 28.3 | H15: 28.3 | I15: 28.3 | J15: 28.3 | K15: 28.3 | L15: 28.3 | M15: 28.3 | N15: 28.3 | O15: 28.3 | P15: 28.3 | Q15: 28.3 | R15: 28.3 | S15: 28.2 | T15: 28.2 | U15: 28.2 | V15: 28.2 | W15: 28.2 | X15: 28.2 | Y15: 28.2 | Z15: 28.2 | AA15: 28.2 | AB15: 28.2 | AC15: 28.2 | AD15: 28.2 | AE15: 28.2 | AF15: 28.2 | AG15: 50 | AH15: =MAX(B15:AF15) -> 29.1 | AI15: =MIN(B15:AF15) -> 28.2
A16: Upper Bhotekoshi Khola(45) | B16: 17.3 | C16: 17.3 | D16: 16.8 | E16: 16.8 | F16: 16.8 | G16: 16.8 | H16: 16.8 | I16: 16.8 | J16: 16.8 | K16: 16.8 | L16: 16.8 | M16: 16.8 | N16: 16.8 | O16: 16.8 | P16: 16.8 | Q16: 16.8 | R16: 16.8 | S16: 16.2 | T16: 16.2 | U16: 16.2 | V16: 16.2 | W16: 16.2 | X16: 16.2 | Y16: 16.2 | Z16: 16.2 | AA16: 16.2 | AB16: 16.2 | AC16: 16.2 | AD16: 16.2 | AE16: 16.2 | AF16: 16.2 | AG16: 45 | AH16: =MAX(B16:AF16) -> 17.3 | AI16: =MIN(B16:AF16) -> 16.2
A17: Super Madi ( 44 ) | B17: 14 | C17: 14 | D17: 14 | E17: 14 | F17: 14 | G17: 14 | H17: 14 | I17: 14 | J17: 14 | K17: 14 | L17: 14 | M17: 14 | N17: 14 | O17: 14 | P17: 14 | Q17: 14 | R17: 14 | S17: 14 | T17: 14 | U17: 14 | V17: 14 | W17: 14 | X17: 14 | Y17: 14 | Z17: 14 | AA17: 14 | AB17: 14 | AC17: 14 | AD17: 14 | AE17: 14 | AF17: 14 | AG17: 44 | AH17: =MAX(B17:AG17) -> 44 | AI17: =MIN(B17:AG17) -> 14
A18: Mistri Khola(42) | B18: 7 | C18: 7 | D18: 7.5 | E18: 7.5 | F18: 7.5 | G18: 7.5 | H18: 7.5 | I18: 7.5 | J18: 7.5 | K18: 7.5 | L18: 7.5 | M18: 7.5 | N18: 7.5 | O18: 7.5 | P18: 7.5 | Q18: 7.5 | R18: 7.5 | S18: 7.8 | T18: 7.8 | U18: 7.8 | V18: 7.8 | W18: 7.8 | X18: 7.8 | Y18: 7.8 | Z18: 7.8 | AA18: 7.8 | AB18: 7.8 | AC18: 7.8 | AD18: 7.8 | AE18: 7.8 | AF18: 7.8 | AG18: 42 | AH18: =MAX(B18:AF18) -> 7.8 | AI18: =MIN(B18:AF18) -> 7
A19: Upper Chameliya(40) | B19: 12.2 | C19: 12.2 | D19: 12.2 | E19: 12.2 | F19: 12.2 | G19: 12.2 | H19: 12.2 | I19: 12.2 | J19: 12.2 | K19: 12.2 | L19: 12.2 | M19: 12.2 | N19: 12.2 | O19: 12.2 | P19: 12.2 | Q19: 12.2 | R19: 12.2 | S19: 12.2 | T19: 12.2 | U19: 12.2 | V19: 12.2 | W19: 12.2 | X19: 12.2 | Y19: 12.2 | Z19: 12.2 | AA19: 12.2 | AB19: 12.2 | AC19: 12.2 | AD19: 12.2 | AE19: 12.2 | AF19: 12.2 | AG19: 38.46 | AH19: =MAX(B19:AF19) -> 12.2 | AI19: =MIN(B19:AF19) -> 12.2
A20: Upper Kalanga Gad(38.46) | B20: 7.8 | C20: 7.8 | D20: 7.8 | E20: 7.8 | F20: 7.8 | G20: 7.8 | H20: 7.8 | I20: 7.8 | J20: 7.8 | K20: 7.8 | L20: 7.8 | M20: 7.8 | N20: 7.8 | O20: 7.8 | P20: 7.8 | Q20: 7.8 | R20: 7.8 | S20: 7.8 | T20: 7.8 | U20: 7.8 | V20: 7.8 | W20: 7.8 | X20: 7.8 | Y20: 7.8 | Z20: 7.8 | AA20: 7.8 | AB20: 7.8 | AC20: 7.8 | AD20: 7.8 | AE20: 7.8 | AF20: 7.8 | AG20: 38.46 | AH20: =MAX(B20:AF20) -> 7.8 | AI20: =MIN(B20:AF20) -> 7.8
A21: Upper Balefi (36) | B21: 13 | C21: 13 | D21: 13 | E21: 13 | F21: 13 | G21: 13 | H21: 13 | I21: 13 | J21: 13 | K21: 13 | L21: 13 | M21: 13 | N21: 13 | O21: 13 | P21: 13 | Q21: 13 | R21: 13 | S21: 13 | T21: 13 | U21: 13 | V21: 13 | W21: 13 | X21: 13 | Y21: 13 | Z21: 13 | AA21: 13 | AB21: 13 | AC21: 13 | AD21: 13 | AE21: 13 | AF21: 13 | AG21: 36 | AH21: =MAX(B21:AF21) -> 13 | AI21: =MIN(B21:AF21) -> 13
A22: Nyadi(30) | B22: 7.8 | C22: 7.8 | D22: 7.8 | E22: 7.8 | F22: 7.8 | G22: 7.8 | H22: 7.8 | I22: 7.8 | J22: 7.8 | K22: 7.8 | L22: 7.8 | M22: 7.8 | N22: 7.8 | O22: 7.8 | P22: 7.8 | Q22: 7.8 | R22: 7.8 | S22: 7.8 | T22: 7.8 | U22: 7.8 | V22: 7.8 | W22: 7.8 | X22: 7.8 | Y22: 7.8 | Z22: 7.8 | AA22: 7.8 | AB22: 7.8 | AC22: 7.8 | AD22: 7.8 | AE22: 7.8 | AF22: 7.8 | AG22: 30 | AH22: =MAX(B22:AF22) -> 7.8 | AI22: =MIN(B22:AF22) -> 7.8
A23: Likhu Khola A(29.04) | B23: 9 | C23: 9 | D23: 9 | E23: 9 | F23: 9 | G23: 9 | H23: 9 | I23: 9 | J23: 9 | K23: 9 | L23: 9 | M23: 9 | N23: 9 | O23: 9 | P23: 9 | Q23: 9 | R23: 9 | S23: 9 | T23: 9 | U23: 9 | V23: 9 | W23: 9 | X23: 9 | Y23: 9 | Z23: 9 | AA23: 9 | AB23: 9 | AC23: 9 | AD23: 9 | AE23: 9 | AF23: 9 | AG23: 24.2 | AH23: =MAX(B23:AF23) -> 9 | AI23: =MIN(B23:AF23) -> 9
A24: Lower Likhu(28) | B24: 8.7 | C24: 8.7 | D24: 8.2 | E24: 8.2 | F24: 8.2 | G24: 8.2 | H24: 8.2 | I24: 8.2 | J24: 8.2 | K24: 8.2 | L24: 8.2 | M24: 8.2 | N24: 8.2 | O24: 8.2 | P24: 8.2 | Q24: 8.2 | R24: 8.2 | S24: 8.2 | T24: 8.2 | U24: 8.2 | V24: 8.2 | W24: 8.2 | X24: 8.2 | Y24: 8.2 | Z24: 8.2 | AA24: 8.2 | AB24: 8.2 | AC24: 8.2 | AD24: 8.2 | AE24: 8.2 | AF24: 8.2 | AG24: 28 | AH24: =MAX(B24:AF24) -> 8.7 | AI24: =MIN(B24:AF24) -> 8.2
A25: Dordi(27) | B25: 6.4 | C25: 6.4 | D25: 6.4 | E25: 6.4 | F25: 6.4 | G25: 6.4 | H25: 6.4 | I25: 6.4 | J25: 6.4 | K25: 6.4 | L25: 6.4 | M25: 6.4 | N25: 6.4 | O25: 6.4 | P25: 6.4 | Q25: 6.4 | R25: 6.4 | S25: 6.4 | T25: 6.4 | U25: 6.4 | V25: 6.4 | W25: 6.4 | X25: 6.4 | Y25: 6.4 | Z25: 6.4 | AA25: 6.4 | AB25: 6.4 | AC25: 6.4 | AD25: 6.4 | AE25: 6.4 | AF25: 6.4 | AG25: 30 | AH25: =MAX(B25:AF25) -> 6.4 | AI25: =MIN(B25:AF25) -> 6.4
A26: Upper Madi(25) | B26: 6.5 | C26: 6.5 | D26: 6.5 | E26: 6.5 | F26: 6.5 | G26: 6.5 | H26: 6.5 | I26: 6.5 | J26: 6.5 | K26: 6.5 | L26: 6.5 | M26: 6.5 | N26: 6.5 | O26: 6.5 | P26: 6.5 | Q26: 6.5 | R26: 6.5 | S26: 6.5 | T26: 6.5 | U26: 6.5 | V26: 6.5 | W26: 6.5 | X26: 6.5 | Y26: 6.5 | Z26: 6.5 | AA26: 6.5 | AB26: 6.5 | AC26: 6.5 | AD26: 6.5 | AE26: 6.5 | AF26: 6.5 | AG26: 25 | AH26: =MAX(B26:AF26) -> 6.5 | AI26: =MIN(B26:AF26) -> 6.5
A27: Kabeli B-1(25) | B27: 5 | C27: 5 | D27: 5 | E27: 5 | F27: 5 | G27: 5 | H27: 5 | I27: 5 | J27: 5 | K27: 5 | L27: 5 | M27: 5 | N27: 5 | O27: 5 | P27: 5 | Q27: 5 | R27: 5 | S27: 5 | T27: 5 | U27: 5 | V27: 5 | W27: 5 | X27: 5 | Y27: 5 | Z27: 5 | AA27: 5 | AB27: 5 | AC27: 5 | AD27: 5 | AE27: 5 | AF27: 5 | AG27: 25 | AH27: =MAX(B27:AF27) -> 5 | AI27: =MIN(B27:AF27) -> 5
A28: Singati Khola(25) | B28: 6 | C28: 6 | D28: 6 | E28: 6 | F28: 6 | G28: 6 | H28: 6 | I28: 6 | J28: 6 | K28: 6 | L28: 6 | M28: 6 | N28: 6 | O28: 6 | P28: 6 | Q28: 6 | R28: 6 | S28: 6 | T28: 6 | U28: 6 | V28: 6 | W28: 6 | X28: 6 | Y28: 6 | Z28: 6 | AA28: 6 | AB28: 6 | AC28: 6 | AD28: 6 | AE28: 6 | AF28: 6 | AG28: 25 | AH28: =MAX(B28:AF28) -> 6 | AI28: =MIN(B28:AF28) -> 6
A29: Upper Dordi (25) | B29: 7.2 | C29: 7.2 | D29: 7.2 | E29: 7.2 | F29: 7.2 | G29: 7.2 | H29: 7.2 | I29: 7.2 | J29: 7.2 | K29: 7.2 | L29: 7.2 | M29: 7.2 | N29: 7.2 | O29: 7.2 | P29: 7.2 | Q29: 7.2 | R29: 7.2 | S29: 7.2 | T29: 7.2 | U29: 7.2 | V29: 7.2 | W29: 7.2 | X29: 7.2 | Y29: 7.2 | Z29: 7.2 | AA29: 7.2 | AB29: 7.2 | AC29: 7.2 | AD29: 7.2 | AE29: 7.2 | AF29: 7.2 | AG29: 25 | AH29: =MAX(B29:AF29) -> 7.2 | AI29: =MIN(B29:AF29) -> 7.2
... A56: Other IPP Total | B56: 150 | C56: 150 | D56: 150 | E56: 150 | F56: 150 | G56: 150 | H56: 150 | I56: 150 | J56: 150 | K56: 150 | L56: 150 | M56: 150 | N56: 150 | O56: 150 | P56: 150 | Q56: 150 | R56: 150 | S56: 150 | T56: 150 | U56: 150 | V56: 150 | W56: 150 | X56: 150 | Y56: 150 | Z56: 150 | AA56: 150 | AB56: 150 | AC56: 150 | AD56: 150 | AE56: 150 | AF56: 150 | AG56: 85 | AH56: =MAX(B56:AF56) -> 150 | AI56: =MIN(B56:AF56) -> 150
